[2025-05-06T14:41:56.973+0000] {taskinstance.py:1956} INFO - Dependencies all met for dep_context=non-requeueable deps ti=<TaskInstance: e_commerce_dw_etl.extract.extract_and_load_to_staging scheduled__2025-01-25T00:00:00+00:00 [queued]>
[2025-05-06T14:41:56.985+0000] {taskinstance.py:1956} INFO - Dependencies all met for dep_context=requeueable deps ti=<TaskInstance: e_commerce_dw_etl.extract.extract_and_load_to_staging scheduled__2025-01-25T00:00:00+00:00 [queued]>
[2025-05-06T14:41:56.986+0000] {taskinstance.py:2170} INFO - Starting attempt 1 of 1
[2025-05-06T14:41:57.014+0000] {taskinstance.py:2191} INFO - Executing <Task(PythonOperator): extract.extract_and_load_to_staging> on 2025-01-25 00:00:00+00:00
[2025-05-06T14:41:57.022+0000] {standard_task_runner.py:60} INFO - Started process 1359 to run task
[2025-05-06T14:41:57.028+0000] {standard_task_runner.py:87} INFO - Running: ['***', 'tasks', 'run', 'e_commerce_dw_etl', 'extract.extract_and_load_to_staging', 'scheduled__2025-01-25T00:00:00+00:00', '--job-id', '94', '--raw', '--subdir', 'DAGS_FOLDER/e_commerce_dw_dag.py', '--cfg-path', '/tmp/tmpltaejwzn']
[2025-05-06T14:41:57.030+0000] {standard_task_runner.py:88} INFO - Job 94: Subtask extract.extract_and_load_to_staging
[2025-05-06T14:41:57.278+0000] {logging_mixin.py:188} WARNING - /home/***/.local/lib/python3.8/site-packages/***/settings.py:194 DeprecationWarning: The sql_alchemy_conn option in [core] has been moved to the sql_alchemy_conn option in [database] - the old setting has been used, but please update your config.
[2025-05-06T14:41:57.328+0000] {task_command.py:423} INFO - Running <TaskInstance: e_commerce_dw_etl.extract.extract_and_load_to_staging scheduled__2025-01-25T00:00:00+00:00 [running]> on host 4e8b8c3535ca
[2025-05-06T14:41:57.442+0000] {taskinstance.py:2480} INFO - Exporting env vars: AIRFLOW_CTX_DAG_OWNER='***' AIRFLOW_CTX_DAG_ID='e_commerce_dw_etl' AIRFLOW_CTX_TASK_ID='extract.extract_and_load_to_staging' AIRFLOW_CTX_EXECUTION_DATE='2025-01-25T00:00:00+00:00' AIRFLOW_CTX_TRY_NUMBER='1' AIRFLOW_CTX_DAG_RUN_ID='scheduled__2025-01-25T00:00:00+00:00'
[2025-05-06T14:41:57.455+0000] {mysql_operator.py:13} ERROR - Can't connect to mysql database
[2025-05-06T14:41:57.476+0000] {taskinstance.py:2698} ERROR - Task failed with exception
Traceback (most recent call last):
  File "/home/airflow/.local/lib/python3.8/site-packages/airflow/models/taskinstance.py", line 433, in _execute_task
    result = execute_callable(context=context, **execute_callable_kwargs)
  File "/home/airflow/.local/lib/python3.8/site-packages/airflow/operators/python.py", line 199, in execute
    return_value = self.execute_callable()
  File "/home/airflow/.local/lib/python3.8/site-packages/airflow/operators/python.py", line 216, in execute_callable
    return self.python_callable(*self.op_args, **self.op_kwargs)
  File "/opt/airflow/dags/extract_data.py", line 30, in extract_and_load_to_staging
    df = source_operator.get_data_to_pd(f"SELECT * FROM {table}")
  File "/opt/airflow/plugins/mysql_operator.py", line 15, in get_data_to_pd
    return self.mysqlhook.get_pandas_df(query)
  File "/home/airflow/.local/lib/python3.8/site-packages/airflow/providers/common/sql/hooks/sql.py", line 220, in get_pandas_df
    with closing(self.get_conn()) as conn:
  File "/home/airflow/.local/lib/python3.8/site-packages/airflow/providers/mysql/hooks/mysql.py", line 187, in get_conn
    conn = self.connection or self.get_connection(getattr(self, self.conn_name_attr))
  File "/home/airflow/.local/lib/python3.8/site-packages/airflow/hooks/base.py", line 82, in get_connection
    conn = Connection.get_connection_from_secrets(conn_id)
  File "/home/airflow/.local/lib/python3.8/site-packages/airflow/models/connection.py", line 479, in get_connection_from_secrets
    raise AirflowNotFoundException(f"The conn_id `{conn_id}` isn't defined")
airflow.exceptions.AirflowNotFoundException: The conn_id `mysql` isn't defined
[2025-05-06T14:41:57.490+0000] {taskinstance.py:1138} INFO - Marking task as FAILED. dag_id=e_commerce_dw_etl, task_id=extract.extract_and_load_to_staging, execution_date=20250125T000000, start_date=20250506T144156, end_date=20250506T144157
[2025-05-06T14:41:57.615+0000] {standard_task_runner.py:107} ERROR - Failed to execute job 94 for task extract.extract_and_load_to_staging (The conn_id `mysql` isn't defined; 1359)
[2025-05-06T14:41:57.642+0000] {local_task_job_runner.py:234} INFO - Task exited with return code 1
[2025-05-06T14:41:57.842+0000] {taskinstance.py:3280} INFO - 0 downstream tasks scheduled from follow-on schedule check
[2025-05-08T10:43:50.241+0000] {taskinstance.py:1956} INFO - Dependencies all met for dep_context=non-requeueable deps ti=<TaskInstance: e_commerce_dw_etl.extract.extract_and_load_to_staging scheduled__2025-01-25T00:00:00+00:00 [queued]>
[2025-05-08T10:43:50.256+0000] {taskinstance.py:1956} INFO - Dependencies all met for dep_context=requeueable deps ti=<TaskInstance: e_commerce_dw_etl.extract.extract_and_load_to_staging scheduled__2025-01-25T00:00:00+00:00 [queued]>
[2025-05-08T10:43:50.257+0000] {taskinstance.py:2170} INFO - Starting attempt 1 of 1
[2025-05-08T10:43:50.287+0000] {taskinstance.py:2191} INFO - Executing <Task(PythonOperator): extract.extract_and_load_to_staging> on 2025-01-25 00:00:00+00:00
[2025-05-08T10:43:50.296+0000] {standard_task_runner.py:60} INFO - Started process 557 to run task
[2025-05-08T10:43:50.300+0000] {standard_task_runner.py:87} INFO - Running: ['***', 'tasks', 'run', 'e_commerce_dw_etl', 'extract.extract_and_load_to_staging', 'scheduled__2025-01-25T00:00:00+00:00', '--job-id', '780', '--raw', '--subdir', 'DAGS_FOLDER/e_commerce_dw_dag.py', '--cfg-path', '/tmp/tmp9de65tk8']
[2025-05-08T10:43:50.304+0000] {standard_task_runner.py:88} INFO - Job 780: Subtask extract.extract_and_load_to_staging
[2025-05-08T10:43:50.558+0000] {logging_mixin.py:188} WARNING - /home/***/.local/lib/python3.8/site-packages/***/settings.py:194 DeprecationWarning: The sql_alchemy_conn option in [core] has been moved to the sql_alchemy_conn option in [database] - the old setting has been used, but please update your config.
[2025-05-08T10:43:50.605+0000] {task_command.py:423} INFO - Running <TaskInstance: e_commerce_dw_etl.extract.extract_and_load_to_staging scheduled__2025-01-25T00:00:00+00:00 [running]> on host 274dc1d73528
[2025-05-08T10:43:50.712+0000] {taskinstance.py:2480} INFO - Exporting env vars: AIRFLOW_CTX_DAG_OWNER='***' AIRFLOW_CTX_DAG_ID='e_commerce_dw_etl' AIRFLOW_CTX_TASK_ID='extract.extract_and_load_to_staging' AIRFLOW_CTX_EXECUTION_DATE='2025-01-25T00:00:00+00:00' AIRFLOW_CTX_TRY_NUMBER='1' AIRFLOW_CTX_DAG_RUN_ID='scheduled__2025-01-25T00:00:00+00:00'
[2025-05-08T10:43:50.728+0000] {mysql_operator.py:13} ERROR - Can't connect to mysql database
[2025-05-08T10:43:50.752+0000] {taskinstance.py:2698} ERROR - Task failed with exception
Traceback (most recent call last):
  File "/home/airflow/.local/lib/python3.8/site-packages/airflow/models/taskinstance.py", line 433, in _execute_task
    result = execute_callable(context=context, **execute_callable_kwargs)
  File "/home/airflow/.local/lib/python3.8/site-packages/airflow/operators/python.py", line 199, in execute
    return_value = self.execute_callable()
  File "/home/airflow/.local/lib/python3.8/site-packages/airflow/operators/python.py", line 216, in execute_callable
    return self.python_callable(*self.op_args, **self.op_kwargs)
  File "/opt/airflow/dags/extract_data.py", line 30, in extract_and_load_to_staging
    df = source_operator.get_data_to_pd(f"SELECT * FROM {table}")
  File "/opt/airflow/plugins/mysql_operator.py", line 15, in get_data_to_pd
    return self.mysqlhook.get_pandas_df(query)
  File "/home/airflow/.local/lib/python3.8/site-packages/airflow/providers/common/sql/hooks/sql.py", line 220, in get_pandas_df
    with closing(self.get_conn()) as conn:
  File "/home/airflow/.local/lib/python3.8/site-packages/airflow/providers/mysql/hooks/mysql.py", line 187, in get_conn
    conn = self.connection or self.get_connection(getattr(self, self.conn_name_attr))
  File "/home/airflow/.local/lib/python3.8/site-packages/airflow/hooks/base.py", line 82, in get_connection
    conn = Connection.get_connection_from_secrets(conn_id)
  File "/home/airflow/.local/lib/python3.8/site-packages/airflow/models/connection.py", line 479, in get_connection_from_secrets
    raise AirflowNotFoundException(f"The conn_id `{conn_id}` isn't defined")
airflow.exceptions.AirflowNotFoundException: The conn_id `mysql` isn't defined
[2025-05-08T10:43:50.766+0000] {taskinstance.py:1138} INFO - Marking task as FAILED. dag_id=e_commerce_dw_etl, task_id=extract.extract_and_load_to_staging, execution_date=20250125T000000, start_date=20250508T104350, end_date=20250508T104350
[2025-05-08T10:43:50.888+0000] {standard_task_runner.py:107} ERROR - Failed to execute job 780 for task extract.extract_and_load_to_staging (The conn_id `mysql` isn't defined; 557)
[2025-05-08T10:43:50.918+0000] {local_task_job_runner.py:234} INFO - Task exited with return code 1
[2025-05-08T10:43:51.131+0000] {taskinstance.py:3280} INFO - 0 downstream tasks scheduled from follow-on schedule check
[2025-05-08T11:06:20.924+0000] {taskinstance.py:1956} INFO - Dependencies all met for dep_context=non-requeueable deps ti=<TaskInstance: e_commerce_dw_etl.extract.extract_and_load_to_staging scheduled__2025-01-25T00:00:00+00:00 [queued]>
[2025-05-08T11:06:20.951+0000] {taskinstance.py:1956} INFO - Dependencies all met for dep_context=requeueable deps ti=<TaskInstance: e_commerce_dw_etl.extract.extract_and_load_to_staging scheduled__2025-01-25T00:00:00+00:00 [queued]>
[2025-05-08T11:06:20.952+0000] {taskinstance.py:2170} INFO - Starting attempt 1 of 1
[2025-05-08T11:06:20.996+0000] {taskinstance.py:2191} INFO - Executing <Task(PythonOperator): extract.extract_and_load_to_staging> on 2025-01-25 00:00:00+00:00
[2025-05-08T11:06:21.011+0000] {standard_task_runner.py:60} INFO - Started process 501 to run task
[2025-05-08T11:06:21.014+0000] {standard_task_runner.py:87} INFO - Running: ['***', 'tasks', 'run', 'e_commerce_dw_etl', 'extract.extract_and_load_to_staging', 'scheduled__2025-01-25T00:00:00+00:00', '--job-id', '978', '--raw', '--subdir', 'DAGS_FOLDER/e_commerce_dw_dag.py', '--cfg-path', '/tmp/tmpy2iendac']
[2025-05-08T11:06:21.017+0000] {standard_task_runner.py:88} INFO - Job 978: Subtask extract.extract_and_load_to_staging
[2025-05-08T11:06:21.301+0000] {logging_mixin.py:188} WARNING - /home/***/.local/lib/python3.8/site-packages/***/settings.py:194 DeprecationWarning: The sql_alchemy_conn option in [core] has been moved to the sql_alchemy_conn option in [database] - the old setting has been used, but please update your config.
[2025-05-08T11:06:21.387+0000] {task_command.py:423} INFO - Running <TaskInstance: e_commerce_dw_etl.extract.extract_and_load_to_staging scheduled__2025-01-25T00:00:00+00:00 [running]> on host 14e98ede325e
[2025-05-08T11:06:21.527+0000] {taskinstance.py:2480} INFO - Exporting env vars: AIRFLOW_CTX_DAG_OWNER='***' AIRFLOW_CTX_DAG_ID='e_commerce_dw_etl' AIRFLOW_CTX_TASK_ID='extract.extract_and_load_to_staging' AIRFLOW_CTX_EXECUTION_DATE='2025-01-25T00:00:00+00:00' AIRFLOW_CTX_TRY_NUMBER='1' AIRFLOW_CTX_DAG_RUN_ID='scheduled__2025-01-25T00:00:00+00:00'
[2025-05-08T11:06:21.543+0000] {mysql_operator.py:13} ERROR - Can't connect to mysql database
[2025-05-08T11:06:21.584+0000] {taskinstance.py:2698} ERROR - Task failed with exception
Traceback (most recent call last):
  File "/home/airflow/.local/lib/python3.8/site-packages/airflow/models/taskinstance.py", line 433, in _execute_task
    result = execute_callable(context=context, **execute_callable_kwargs)
  File "/home/airflow/.local/lib/python3.8/site-packages/airflow/operators/python.py", line 199, in execute
    return_value = self.execute_callable()
  File "/home/airflow/.local/lib/python3.8/site-packages/airflow/operators/python.py", line 216, in execute_callable
    return self.python_callable(*self.op_args, **self.op_kwargs)
  File "/opt/airflow/dags/extract_data.py", line 30, in extract_and_load_to_staging
    df = source_operator.get_data_to_pd(f"SELECT * FROM {table}")
  File "/opt/airflow/plugins/mysql_operator.py", line 15, in get_data_to_pd
    return self.mysqlhook.get_pandas_df(query)
  File "/home/airflow/.local/lib/python3.8/site-packages/airflow/providers/common/sql/hooks/sql.py", line 220, in get_pandas_df
    with closing(self.get_conn()) as conn:
  File "/home/airflow/.local/lib/python3.8/site-packages/airflow/providers/mysql/hooks/mysql.py", line 187, in get_conn
    conn = self.connection or self.get_connection(getattr(self, self.conn_name_attr))
  File "/home/airflow/.local/lib/python3.8/site-packages/airflow/hooks/base.py", line 82, in get_connection
    conn = Connection.get_connection_from_secrets(conn_id)
  File "/home/airflow/.local/lib/python3.8/site-packages/airflow/models/connection.py", line 479, in get_connection_from_secrets
    raise AirflowNotFoundException(f"The conn_id `{conn_id}` isn't defined")
airflow.exceptions.AirflowNotFoundException: The conn_id `mysql` isn't defined
[2025-05-08T11:06:21.607+0000] {taskinstance.py:1138} INFO - Marking task as FAILED. dag_id=e_commerce_dw_etl, task_id=extract.extract_and_load_to_staging, execution_date=20250125T000000, start_date=20250508T110620, end_date=20250508T110621
[2025-05-08T11:06:21.634+0000] {standard_task_runner.py:107} ERROR - Failed to execute job 978 for task extract.extract_and_load_to_staging (The conn_id `mysql` isn't defined; 501)
[2025-05-08T11:06:21.678+0000] {local_task_job_runner.py:234} INFO - Task exited with return code 1
[2025-05-08T11:06:21.875+0000] {taskinstance.py:3280} INFO - 0 downstream tasks scheduled from follow-on schedule check
[2025-05-08T11:09:26.871+0000] {taskinstance.py:1956} INFO - Dependencies all met for dep_context=non-requeueable deps ti=<TaskInstance: e_commerce_dw_etl.extract.extract_and_load_to_staging scheduled__2025-01-25T00:00:00+00:00 [queued]>
[2025-05-08T11:09:26.884+0000] {taskinstance.py:1956} INFO - Dependencies all met for dep_context=requeueable deps ti=<TaskInstance: e_commerce_dw_etl.extract.extract_and_load_to_staging scheduled__2025-01-25T00:00:00+00:00 [queued]>
[2025-05-08T11:09:26.885+0000] {taskinstance.py:2170} INFO - Starting attempt 1 of 1
[2025-05-08T11:09:26.905+0000] {taskinstance.py:2191} INFO - Executing <Task(PythonOperator): extract.extract_and_load_to_staging> on 2025-01-25 00:00:00+00:00
[2025-05-08T11:09:26.912+0000] {standard_task_runner.py:60} INFO - Started process 1012 to run task
[2025-05-08T11:09:26.917+0000] {standard_task_runner.py:87} INFO - Running: ['***', 'tasks', 'run', 'e_commerce_dw_etl', 'extract.extract_and_load_to_staging', 'scheduled__2025-01-25T00:00:00+00:00', '--job-id', '1173', '--raw', '--subdir', 'DAGS_FOLDER/e_commerce_dw_dag.py', '--cfg-path', '/tmp/tmp_f6nba6z']
[2025-05-08T11:09:26.919+0000] {standard_task_runner.py:88} INFO - Job 1173: Subtask extract.extract_and_load_to_staging
[2025-05-08T11:09:27.091+0000] {logging_mixin.py:188} WARNING - /home/***/.local/lib/python3.8/site-packages/***/settings.py:194 DeprecationWarning: The sql_alchemy_conn option in [core] has been moved to the sql_alchemy_conn option in [database] - the old setting has been used, but please update your config.
[2025-05-08T11:09:27.156+0000] {task_command.py:423} INFO - Running <TaskInstance: e_commerce_dw_etl.extract.extract_and_load_to_staging scheduled__2025-01-25T00:00:00+00:00 [running]> on host 14e98ede325e
[2025-05-08T11:09:27.275+0000] {taskinstance.py:2480} INFO - Exporting env vars: AIRFLOW_CTX_DAG_OWNER='***' AIRFLOW_CTX_DAG_ID='e_commerce_dw_etl' AIRFLOW_CTX_TASK_ID='extract.extract_and_load_to_staging' AIRFLOW_CTX_EXECUTION_DATE='2025-01-25T00:00:00+00:00' AIRFLOW_CTX_TRY_NUMBER='1' AIRFLOW_CTX_DAG_RUN_ID='scheduled__2025-01-25T00:00:00+00:00'
[2025-05-08T11:09:27.287+0000] {crypto.py:82} WARNING - empty cryptography key - values will not be stored encrypted.
[2025-05-08T11:09:27.289+0000] {connection.py:473} ERROR - Unable to retrieve connection from secrets backend (MetastoreBackend). Checking subsequent secrets backend.
Traceback (most recent call last):
  File "/home/airflow/.local/lib/python3.8/site-packages/airflow/models/connection.py", line 468, in get_connection_from_secrets
    conn = secrets_backend.get_connection(conn_id=conn_id)
  File "/home/airflow/.local/lib/python3.8/site-packages/airflow/utils/session.py", line 79, in wrapper
    return func(*args, session=session, **kwargs)
  File "/home/airflow/.local/lib/python3.8/site-packages/airflow/secrets/metastore.py", line 42, in get_connection
    return MetastoreBackend._fetch_connection(conn_id, session=session)
  File "/home/airflow/.local/lib/python3.8/site-packages/airflow/api_internal/internal_api_call.py", line 114, in wrapper
    return func(*args, **kwargs)
  File "/home/airflow/.local/lib/python3.8/site-packages/airflow/utils/session.py", line 76, in wrapper
    return func(*args, **kwargs)
  File "/home/airflow/.local/lib/python3.8/site-packages/airflow/secrets/metastore.py", line 73, in _fetch_connection
    conn = session.scalar(select(Connection).where(Connection.conn_id == conn_id).limit(1))
  File "/home/airflow/.local/lib/python3.8/site-packages/sqlalchemy/orm/session.py", line 1747, in scalar
    return self.execute(
  File "/home/airflow/.local/lib/python3.8/site-packages/sqlalchemy/engine/result.py", line 1276, in scalar
    return self._only_one_row(
  File "/home/airflow/.local/lib/python3.8/site-packages/sqlalchemy/engine/result.py", line 559, in _only_one_row
    row = onerow(hard_close=True)
  File "/home/airflow/.local/lib/python3.8/site-packages/sqlalchemy/engine/result.py", line 1801, in _fetchone_impl
    row = next(self.iterator, _NO_ROW)
  File "/home/airflow/.local/lib/python3.8/site-packages/sqlalchemy/orm/loading.py", line 151, in chunks
    rows = [proc(row) for row in fetch]
  File "/home/airflow/.local/lib/python3.8/site-packages/sqlalchemy/orm/loading.py", line 151, in <listcomp>
    rows = [proc(row) for row in fetch]
  File "/home/airflow/.local/lib/python3.8/site-packages/sqlalchemy/orm/loading.py", line 984, in _instance
    state.manager.dispatch.load(state, context)
  File "/home/airflow/.local/lib/python3.8/site-packages/sqlalchemy/event/attr.py", line 346, in __call__
    fn(*args, **kw)
  File "/home/airflow/.local/lib/python3.8/site-packages/sqlalchemy/orm/mapper.py", line 3702, in _event_on_load
    instrumenting_mapper._reconstructor(state.obj())
  File "/home/airflow/.local/lib/python3.8/site-packages/airflow/models/connection.py", line 174, in on_db_load
    if self.password:
  File "/home/airflow/.local/lib/python3.8/site-packages/sqlalchemy/orm/attributes.py", line 606, in __get__
    retval = self.descriptor.__get__(instance, owner)
  File "/home/airflow/.local/lib/python3.8/site-packages/airflow/models/connection.py", line 296, in get_password
    raise AirflowException(
airflow.exceptions.AirflowException: Can't decrypt encrypted password for login=***  FERNET_KEY configuration is missing
[2025-05-08T11:09:27.297+0000] {mysql_operator.py:13} ERROR - Can't connect to mysql database
[2025-05-08T11:09:27.312+0000] {connection.py:473} ERROR - Unable to retrieve connection from secrets backend (MetastoreBackend). Checking subsequent secrets backend.
Traceback (most recent call last):
  File "/home/airflow/.local/lib/python3.8/site-packages/airflow/models/connection.py", line 468, in get_connection_from_secrets
    conn = secrets_backend.get_connection(conn_id=conn_id)
  File "/home/airflow/.local/lib/python3.8/site-packages/airflow/utils/session.py", line 79, in wrapper
    return func(*args, session=session, **kwargs)
  File "/home/airflow/.local/lib/python3.8/site-packages/airflow/secrets/metastore.py", line 42, in get_connection
    return MetastoreBackend._fetch_connection(conn_id, session=session)
  File "/home/airflow/.local/lib/python3.8/site-packages/airflow/api_internal/internal_api_call.py", line 114, in wrapper
    return func(*args, **kwargs)
  File "/home/airflow/.local/lib/python3.8/site-packages/airflow/utils/session.py", line 76, in wrapper
    return func(*args, **kwargs)
  File "/home/airflow/.local/lib/python3.8/site-packages/airflow/secrets/metastore.py", line 73, in _fetch_connection
    conn = session.scalar(select(Connection).where(Connection.conn_id == conn_id).limit(1))
  File "/home/airflow/.local/lib/python3.8/site-packages/sqlalchemy/orm/session.py", line 1747, in scalar
    return self.execute(
  File "/home/airflow/.local/lib/python3.8/site-packages/sqlalchemy/engine/result.py", line 1276, in scalar
    return self._only_one_row(
  File "/home/airflow/.local/lib/python3.8/site-packages/sqlalchemy/engine/result.py", line 559, in _only_one_row
    row = onerow(hard_close=True)
  File "/home/airflow/.local/lib/python3.8/site-packages/sqlalchemy/engine/result.py", line 1801, in _fetchone_impl
    row = next(self.iterator, _NO_ROW)
  File "/home/airflow/.local/lib/python3.8/site-packages/sqlalchemy/orm/loading.py", line 151, in chunks
    rows = [proc(row) for row in fetch]
  File "/home/airflow/.local/lib/python3.8/site-packages/sqlalchemy/orm/loading.py", line 151, in <listcomp>
    rows = [proc(row) for row in fetch]
  File "/home/airflow/.local/lib/python3.8/site-packages/sqlalchemy/orm/loading.py", line 984, in _instance
    state.manager.dispatch.load(state, context)
  File "/home/airflow/.local/lib/python3.8/site-packages/sqlalchemy/event/attr.py", line 346, in __call__
    fn(*args, **kw)
  File "/home/airflow/.local/lib/python3.8/site-packages/sqlalchemy/orm/mapper.py", line 3702, in _event_on_load
    instrumenting_mapper._reconstructor(state.obj())
  File "/home/airflow/.local/lib/python3.8/site-packages/airflow/models/connection.py", line 174, in on_db_load
    if self.password:
  File "/home/airflow/.local/lib/python3.8/site-packages/sqlalchemy/orm/attributes.py", line 606, in __get__
    retval = self.descriptor.__get__(instance, owner)
  File "/home/airflow/.local/lib/python3.8/site-packages/airflow/models/connection.py", line 296, in get_password
    raise AirflowException(
airflow.exceptions.AirflowException: Can't decrypt encrypted password for login=***  FERNET_KEY configuration is missing
[2025-05-08T11:09:27.328+0000] {taskinstance.py:2698} ERROR - Task failed with exception
Traceback (most recent call last):
  File "/home/airflow/.local/lib/python3.8/site-packages/airflow/models/taskinstance.py", line 433, in _execute_task
    result = execute_callable(context=context, **execute_callable_kwargs)
  File "/home/airflow/.local/lib/python3.8/site-packages/airflow/operators/python.py", line 199, in execute
    return_value = self.execute_callable()
  File "/home/airflow/.local/lib/python3.8/site-packages/airflow/operators/python.py", line 216, in execute_callable
    return self.python_callable(*self.op_args, **self.op_kwargs)
  File "/opt/airflow/dags/extract_data.py", line 30, in extract_and_load_to_staging
    df = source_operator.get_data_to_pd(f"SELECT * FROM {table}")
  File "/opt/airflow/plugins/mysql_operator.py", line 15, in get_data_to_pd
    return self.mysqlhook.get_pandas_df(query)
  File "/home/airflow/.local/lib/python3.8/site-packages/airflow/providers/common/sql/hooks/sql.py", line 220, in get_pandas_df
    with closing(self.get_conn()) as conn:
  File "/home/airflow/.local/lib/python3.8/site-packages/airflow/providers/mysql/hooks/mysql.py", line 187, in get_conn
    conn = self.connection or self.get_connection(getattr(self, self.conn_name_attr))
  File "/home/airflow/.local/lib/python3.8/site-packages/airflow/hooks/base.py", line 82, in get_connection
    conn = Connection.get_connection_from_secrets(conn_id)
  File "/home/airflow/.local/lib/python3.8/site-packages/airflow/models/connection.py", line 479, in get_connection_from_secrets
    raise AirflowNotFoundException(f"The conn_id `{conn_id}` isn't defined")
airflow.exceptions.AirflowNotFoundException: The conn_id `mysql` isn't defined
[2025-05-08T11:09:27.344+0000] {taskinstance.py:1138} INFO - Marking task as FAILED. dag_id=e_commerce_dw_etl, task_id=extract.extract_and_load_to_staging, execution_date=20250125T000000, start_date=20250508T110926, end_date=20250508T110927
[2025-05-08T11:09:27.369+0000] {standard_task_runner.py:107} ERROR - Failed to execute job 1173 for task extract.extract_and_load_to_staging (The conn_id `mysql` isn't defined; 1012)
[2025-05-08T11:09:27.412+0000] {local_task_job_runner.py:234} INFO - Task exited with return code 1
[2025-05-08T11:09:27.772+0000] {taskinstance.py:3280} INFO - 0 downstream tasks scheduled from follow-on schedule check
[2025-05-08T11:15:15.619+0000] {taskinstance.py:1956} INFO - Dependencies all met for dep_context=non-requeueable deps ti=<TaskInstance: e_commerce_dw_etl.extract.extract_and_load_to_staging scheduled__2025-01-25T00:00:00+00:00 [queued]>
[2025-05-08T11:15:15.636+0000] {taskinstance.py:1956} INFO - Dependencies all met for dep_context=requeueable deps ti=<TaskInstance: e_commerce_dw_etl.extract.extract_and_load_to_staging scheduled__2025-01-25T00:00:00+00:00 [queued]>
[2025-05-08T11:15:15.636+0000] {taskinstance.py:2170} INFO - Starting attempt 1 of 1
[2025-05-08T11:15:15.724+0000] {taskinstance.py:2191} INFO - Executing <Task(PythonOperator): extract.extract_and_load_to_staging> on 2025-01-25 00:00:00+00:00
[2025-05-08T11:15:15.731+0000] {standard_task_runner.py:60} INFO - Started process 437 to run task
[2025-05-08T11:15:15.733+0000] {standard_task_runner.py:87} INFO - Running: ['***', 'tasks', 'run', 'e_commerce_dw_etl', 'extract.extract_and_load_to_staging', 'scheduled__2025-01-25T00:00:00+00:00', '--job-id', '1368', '--raw', '--subdir', 'DAGS_FOLDER/e_commerce_dw_dag.py', '--cfg-path', '/tmp/tmppvwqbur7']
[2025-05-08T11:15:15.736+0000] {standard_task_runner.py:88} INFO - Job 1368: Subtask extract.extract_and_load_to_staging
[2025-05-08T11:15:15.942+0000] {logging_mixin.py:188} WARNING - /home/***/.local/lib/python3.8/site-packages/***/settings.py:194 DeprecationWarning: The sql_alchemy_conn option in [core] has been moved to the sql_alchemy_conn option in [database] - the old setting has been used, but please update your config.
[2025-05-08T11:15:15.995+0000] {task_command.py:423} INFO - Running <TaskInstance: e_commerce_dw_etl.extract.extract_and_load_to_staging scheduled__2025-01-25T00:00:00+00:00 [running]> on host 3623a279d4d4
[2025-05-08T11:15:16.118+0000] {taskinstance.py:2480} INFO - Exporting env vars: AIRFLOW_CTX_DAG_OWNER='***' AIRFLOW_CTX_DAG_ID='e_commerce_dw_etl' AIRFLOW_CTX_TASK_ID='extract.extract_and_load_to_staging' AIRFLOW_CTX_EXECUTION_DATE='2025-01-25T00:00:00+00:00' AIRFLOW_CTX_TRY_NUMBER='1' AIRFLOW_CTX_DAG_RUN_ID='scheduled__2025-01-25T00:00:00+00:00'
[2025-05-08T11:15:16.132+0000] {mysql_operator.py:13} ERROR - Can't connect to mysql_default database
[2025-05-08T11:15:16.154+0000] {taskinstance.py:2698} ERROR - Task failed with exception
Traceback (most recent call last):
  File "/home/airflow/.local/lib/python3.8/site-packages/airflow/models/taskinstance.py", line 433, in _execute_task
    result = execute_callable(context=context, **execute_callable_kwargs)
  File "/home/airflow/.local/lib/python3.8/site-packages/airflow/operators/python.py", line 199, in execute
    return_value = self.execute_callable()
  File "/home/airflow/.local/lib/python3.8/site-packages/airflow/operators/python.py", line 216, in execute_callable
    return self.python_callable(*self.op_args, **self.op_kwargs)
  File "/opt/airflow/dags/extract_data.py", line 30, in extract_and_load_to_staging
    df = source_operator.get_data_to_pd(f"SELECT * FROM {table}")
  File "/opt/airflow/plugins/mysql_operator.py", line 15, in get_data_to_pd
    return self.mysqlhook.get_pandas_df(query)
  File "/home/airflow/.local/lib/python3.8/site-packages/airflow/providers/common/sql/hooks/sql.py", line 220, in get_pandas_df
    with closing(self.get_conn()) as conn:
  File "/home/airflow/.local/lib/python3.8/site-packages/airflow/providers/mysql/hooks/mysql.py", line 187, in get_conn
    conn = self.connection or self.get_connection(getattr(self, self.conn_name_attr))
  File "/home/airflow/.local/lib/python3.8/site-packages/airflow/hooks/base.py", line 82, in get_connection
    conn = Connection.get_connection_from_secrets(conn_id)
  File "/home/airflow/.local/lib/python3.8/site-packages/airflow/models/connection.py", line 479, in get_connection_from_secrets
    raise AirflowNotFoundException(f"The conn_id `{conn_id}` isn't defined")
airflow.exceptions.AirflowNotFoundException: The conn_id `mysql_default` isn't defined
[2025-05-08T11:15:16.170+0000] {taskinstance.py:1138} INFO - Marking task as FAILED. dag_id=e_commerce_dw_etl, task_id=extract.extract_and_load_to_staging, execution_date=20250125T000000, start_date=20250508T111515, end_date=20250508T111516
[2025-05-08T11:15:16.188+0000] {standard_task_runner.py:107} ERROR - Failed to execute job 1368 for task extract.extract_and_load_to_staging (The conn_id `mysql_default` isn't defined; 437)
[2025-05-08T11:15:16.230+0000] {local_task_job_runner.py:234} INFO - Task exited with return code 1
[2025-05-08T11:15:16.515+0000] {taskinstance.py:3280} INFO - 0 downstream tasks scheduled from follow-on schedule check
[2025-05-08T11:20:28.469+0000] {taskinstance.py:1956} INFO - Dependencies all met for dep_context=non-requeueable deps ti=<TaskInstance: e_commerce_dw_etl.extract.extract_and_load_to_staging scheduled__2025-01-25T00:00:00+00:00 [queued]>
[2025-05-08T11:20:28.511+0000] {taskinstance.py:1956} INFO - Dependencies all met for dep_context=requeueable deps ti=<TaskInstance: e_commerce_dw_etl.extract.extract_and_load_to_staging scheduled__2025-01-25T00:00:00+00:00 [queued]>
[2025-05-08T11:20:28.513+0000] {taskinstance.py:2170} INFO - Starting attempt 1 of 1
[2025-05-08T11:20:28.570+0000] {taskinstance.py:2191} INFO - Executing <Task(PythonOperator): extract.extract_and_load_to_staging> on 2025-01-25 00:00:00+00:00
[2025-05-08T11:20:28.585+0000] {standard_task_runner.py:60} INFO - Started process 1227 to run task
[2025-05-08T11:20:28.600+0000] {standard_task_runner.py:87} INFO - Running: ['***', 'tasks', 'run', 'e_commerce_dw_etl', 'extract.extract_and_load_to_staging', 'scheduled__2025-01-25T00:00:00+00:00', '--job-id', '1663', '--raw', '--subdir', 'DAGS_FOLDER/e_commerce_dw_dag.py', '--cfg-path', '/tmp/tmpvu0zr4ig']
[2025-05-08T11:20:28.607+0000] {standard_task_runner.py:88} INFO - Job 1663: Subtask extract.extract_and_load_to_staging
[2025-05-08T11:20:28.908+0000] {logging_mixin.py:188} WARNING - /home/***/.local/lib/python3.8/site-packages/***/settings.py:194 DeprecationWarning: The sql_alchemy_conn option in [core] has been moved to the sql_alchemy_conn option in [database] - the old setting has been used, but please update your config.
[2025-05-08T11:20:28.987+0000] {task_command.py:423} INFO - Running <TaskInstance: e_commerce_dw_etl.extract.extract_and_load_to_staging scheduled__2025-01-25T00:00:00+00:00 [running]> on host 3623a279d4d4
[2025-05-08T11:20:29.133+0000] {taskinstance.py:2480} INFO - Exporting env vars: AIRFLOW_CTX_DAG_OWNER='***' AIRFLOW_CTX_DAG_ID='e_commerce_dw_etl' AIRFLOW_CTX_TASK_ID='extract.extract_and_load_to_staging' AIRFLOW_CTX_EXECUTION_DATE='2025-01-25T00:00:00+00:00' AIRFLOW_CTX_TRY_NUMBER='1' AIRFLOW_CTX_DAG_RUN_ID='scheduled__2025-01-25T00:00:00+00:00'
[2025-05-08T11:20:29.153+0000] {crypto.py:82} WARNING - empty cryptography key - values will not be stored encrypted.
[2025-05-08T11:20:29.156+0000] {connection.py:473} ERROR - Unable to retrieve connection from secrets backend (MetastoreBackend). Checking subsequent secrets backend.
Traceback (most recent call last):
  File "/home/airflow/.local/lib/python3.8/site-packages/airflow/models/connection.py", line 468, in get_connection_from_secrets
    conn = secrets_backend.get_connection(conn_id=conn_id)
  File "/home/airflow/.local/lib/python3.8/site-packages/airflow/utils/session.py", line 79, in wrapper
    return func(*args, session=session, **kwargs)
  File "/home/airflow/.local/lib/python3.8/site-packages/airflow/secrets/metastore.py", line 42, in get_connection
    return MetastoreBackend._fetch_connection(conn_id, session=session)
  File "/home/airflow/.local/lib/python3.8/site-packages/airflow/api_internal/internal_api_call.py", line 114, in wrapper
    return func(*args, **kwargs)
  File "/home/airflow/.local/lib/python3.8/site-packages/airflow/utils/session.py", line 76, in wrapper
    return func(*args, **kwargs)
  File "/home/airflow/.local/lib/python3.8/site-packages/airflow/secrets/metastore.py", line 73, in _fetch_connection
    conn = session.scalar(select(Connection).where(Connection.conn_id == conn_id).limit(1))
  File "/home/airflow/.local/lib/python3.8/site-packages/sqlalchemy/orm/session.py", line 1747, in scalar
    return self.execute(
  File "/home/airflow/.local/lib/python3.8/site-packages/sqlalchemy/engine/result.py", line 1276, in scalar
    return self._only_one_row(
  File "/home/airflow/.local/lib/python3.8/site-packages/sqlalchemy/engine/result.py", line 559, in _only_one_row
    row = onerow(hard_close=True)
  File "/home/airflow/.local/lib/python3.8/site-packages/sqlalchemy/engine/result.py", line 1801, in _fetchone_impl
    row = next(self.iterator, _NO_ROW)
  File "/home/airflow/.local/lib/python3.8/site-packages/sqlalchemy/orm/loading.py", line 151, in chunks
    rows = [proc(row) for row in fetch]
  File "/home/airflow/.local/lib/python3.8/site-packages/sqlalchemy/orm/loading.py", line 151, in <listcomp>
    rows = [proc(row) for row in fetch]
  File "/home/airflow/.local/lib/python3.8/site-packages/sqlalchemy/orm/loading.py", line 984, in _instance
    state.manager.dispatch.load(state, context)
  File "/home/airflow/.local/lib/python3.8/site-packages/sqlalchemy/event/attr.py", line 346, in __call__
    fn(*args, **kw)
  File "/home/airflow/.local/lib/python3.8/site-packages/sqlalchemy/orm/mapper.py", line 3702, in _event_on_load
    instrumenting_mapper._reconstructor(state.obj())
  File "/home/airflow/.local/lib/python3.8/site-packages/airflow/models/connection.py", line 174, in on_db_load
    if self.password:
  File "/home/airflow/.local/lib/python3.8/site-packages/sqlalchemy/orm/attributes.py", line 606, in __get__
    retval = self.descriptor.__get__(instance, owner)
  File "/home/airflow/.local/lib/python3.8/site-packages/airflow/models/connection.py", line 296, in get_password
    raise AirflowException(
airflow.exceptions.AirflowException: Can't decrypt encrypted password for login=***  FERNET_KEY configuration is missing
[2025-05-08T11:20:29.163+0000] {mysql_operator.py:13} ERROR - Can't connect to mysql database
[2025-05-08T11:20:29.184+0000] {connection.py:473} ERROR - Unable to retrieve connection from secrets backend (MetastoreBackend). Checking subsequent secrets backend.
Traceback (most recent call last):
  File "/home/airflow/.local/lib/python3.8/site-packages/airflow/models/connection.py", line 468, in get_connection_from_secrets
    conn = secrets_backend.get_connection(conn_id=conn_id)
  File "/home/airflow/.local/lib/python3.8/site-packages/airflow/utils/session.py", line 79, in wrapper
    return func(*args, session=session, **kwargs)
  File "/home/airflow/.local/lib/python3.8/site-packages/airflow/secrets/metastore.py", line 42, in get_connection
    return MetastoreBackend._fetch_connection(conn_id, session=session)
  File "/home/airflow/.local/lib/python3.8/site-packages/airflow/api_internal/internal_api_call.py", line 114, in wrapper
    return func(*args, **kwargs)
  File "/home/airflow/.local/lib/python3.8/site-packages/airflow/utils/session.py", line 76, in wrapper
    return func(*args, **kwargs)
  File "/home/airflow/.local/lib/python3.8/site-packages/airflow/secrets/metastore.py", line 73, in _fetch_connection
    conn = session.scalar(select(Connection).where(Connection.conn_id == conn_id).limit(1))
  File "/home/airflow/.local/lib/python3.8/site-packages/sqlalchemy/orm/session.py", line 1747, in scalar
    return self.execute(
  File "/home/airflow/.local/lib/python3.8/site-packages/sqlalchemy/engine/result.py", line 1276, in scalar
    return self._only_one_row(
  File "/home/airflow/.local/lib/python3.8/site-packages/sqlalchemy/engine/result.py", line 559, in _only_one_row
    row = onerow(hard_close=True)
  File "/home/airflow/.local/lib/python3.8/site-packages/sqlalchemy/engine/result.py", line 1801, in _fetchone_impl
    row = next(self.iterator, _NO_ROW)
  File "/home/airflow/.local/lib/python3.8/site-packages/sqlalchemy/orm/loading.py", line 151, in chunks
    rows = [proc(row) for row in fetch]
  File "/home/airflow/.local/lib/python3.8/site-packages/sqlalchemy/orm/loading.py", line 151, in <listcomp>
    rows = [proc(row) for row in fetch]
  File "/home/airflow/.local/lib/python3.8/site-packages/sqlalchemy/orm/loading.py", line 984, in _instance
    state.manager.dispatch.load(state, context)
  File "/home/airflow/.local/lib/python3.8/site-packages/sqlalchemy/event/attr.py", line 346, in __call__
    fn(*args, **kw)
  File "/home/airflow/.local/lib/python3.8/site-packages/sqlalchemy/orm/mapper.py", line 3702, in _event_on_load
    instrumenting_mapper._reconstructor(state.obj())
  File "/home/airflow/.local/lib/python3.8/site-packages/airflow/models/connection.py", line 174, in on_db_load
    if self.password:
  File "/home/airflow/.local/lib/python3.8/site-packages/sqlalchemy/orm/attributes.py", line 606, in __get__
    retval = self.descriptor.__get__(instance, owner)
  File "/home/airflow/.local/lib/python3.8/site-packages/airflow/models/connection.py", line 296, in get_password
    raise AirflowException(
airflow.exceptions.AirflowException: Can't decrypt encrypted password for login=***  FERNET_KEY configuration is missing
[2025-05-08T11:20:29.215+0000] {taskinstance.py:2698} ERROR - Task failed with exception
Traceback (most recent call last):
  File "/home/airflow/.local/lib/python3.8/site-packages/airflow/models/taskinstance.py", line 433, in _execute_task
    result = execute_callable(context=context, **execute_callable_kwargs)
  File "/home/airflow/.local/lib/python3.8/site-packages/airflow/operators/python.py", line 199, in execute
    return_value = self.execute_callable()
  File "/home/airflow/.local/lib/python3.8/site-packages/airflow/operators/python.py", line 216, in execute_callable
    return self.python_callable(*self.op_args, **self.op_kwargs)
  File "/opt/airflow/dags/extract_data.py", line 30, in extract_and_load_to_staging
    df = source_operator.get_data_to_pd(f"SELECT * FROM {table}")
  File "/opt/airflow/plugins/mysql_operator.py", line 15, in get_data_to_pd
    return self.mysqlhook.get_pandas_df(query)
  File "/home/airflow/.local/lib/python3.8/site-packages/airflow/providers/common/sql/hooks/sql.py", line 220, in get_pandas_df
    with closing(self.get_conn()) as conn:
  File "/home/airflow/.local/lib/python3.8/site-packages/airflow/providers/mysql/hooks/mysql.py", line 187, in get_conn
    conn = self.connection or self.get_connection(getattr(self, self.conn_name_attr))
  File "/home/airflow/.local/lib/python3.8/site-packages/airflow/hooks/base.py", line 82, in get_connection
    conn = Connection.get_connection_from_secrets(conn_id)
  File "/home/airflow/.local/lib/python3.8/site-packages/airflow/models/connection.py", line 479, in get_connection_from_secrets
    raise AirflowNotFoundException(f"The conn_id `{conn_id}` isn't defined")
airflow.exceptions.AirflowNotFoundException: The conn_id `mysql` isn't defined
[2025-05-08T11:20:29.250+0000] {taskinstance.py:1138} INFO - Marking task as FAILED. dag_id=e_commerce_dw_etl, task_id=extract.extract_and_load_to_staging, execution_date=20250125T000000, start_date=20250508T112028, end_date=20250508T112029
[2025-05-08T11:20:29.274+0000] {standard_task_runner.py:107} ERROR - Failed to execute job 1663 for task extract.extract_and_load_to_staging (The conn_id `mysql` isn't defined; 1227)
[2025-05-08T11:20:29.313+0000] {local_task_job_runner.py:234} INFO - Task exited with return code 1
[2025-05-08T11:20:29.712+0000] {taskinstance.py:3280} INFO - 0 downstream tasks scheduled from follow-on schedule check
