[2025-05-06T14:42:19.498+0000] {taskinstance.py:1956} INFO - Dependencies all met for dep_context=non-requeueable deps ti=<TaskInstance: e_commerce_dw_etl.extract.extract_and_load_to_staging scheduled__2025-03-09T00:00:00+00:00 [queued]>
[2025-05-06T14:42:19.510+0000] {taskinstance.py:1956} INFO - Dependencies all met for dep_context=requeueable deps ti=<TaskInstance: e_commerce_dw_etl.extract.extract_and_load_to_staging scheduled__2025-03-09T00:00:00+00:00 [queued]>
[2025-05-06T14:42:19.512+0000] {taskinstance.py:2170} INFO - Starting attempt 1 of 1
[2025-05-06T14:42:19.543+0000] {taskinstance.py:2191} INFO - Executing <Task(PythonOperator): extract.extract_and_load_to_staging> on 2025-03-09 00:00:00+00:00
[2025-05-06T14:42:19.551+0000] {standard_task_runner.py:60} INFO - Started process 1465 to run task
[2025-05-06T14:42:19.556+0000] {standard_task_runner.py:87} INFO - Running: ['***', 'tasks', 'run', 'e_commerce_dw_etl', 'extract.extract_and_load_to_staging', 'scheduled__2025-03-09T00:00:00+00:00', '--job-id', '137', '--raw', '--subdir', 'DAGS_FOLDER/e_commerce_dw_dag.py', '--cfg-path', '/tmp/tmpacstlg9z']
[2025-05-06T14:42:19.560+0000] {standard_task_runner.py:88} INFO - Job 137: Subtask extract.extract_and_load_to_staging
[2025-05-06T14:42:19.792+0000] {logging_mixin.py:188} WARNING - /home/***/.local/lib/python3.8/site-packages/***/settings.py:194 DeprecationWarning: The sql_alchemy_conn option in [core] has been moved to the sql_alchemy_conn option in [database] - the old setting has been used, but please update your config.
[2025-05-06T14:42:19.845+0000] {task_command.py:423} INFO - Running <TaskInstance: e_commerce_dw_etl.extract.extract_and_load_to_staging scheduled__2025-03-09T00:00:00+00:00 [running]> on host 4e8b8c3535ca
[2025-05-06T14:42:19.942+0000] {taskinstance.py:2480} INFO - Exporting env vars: AIRFLOW_CTX_DAG_OWNER='***' AIRFLOW_CTX_DAG_ID='e_commerce_dw_etl' AIRFLOW_CTX_TASK_ID='extract.extract_and_load_to_staging' AIRFLOW_CTX_EXECUTION_DATE='2025-03-09T00:00:00+00:00' AIRFLOW_CTX_TRY_NUMBER='1' AIRFLOW_CTX_DAG_RUN_ID='scheduled__2025-03-09T00:00:00+00:00'
[2025-05-06T14:42:19.954+0000] {mysql_operator.py:13} ERROR - Can't connect to mysql database
[2025-05-06T14:42:19.970+0000] {taskinstance.py:2698} ERROR - Task failed with exception
Traceback (most recent call last):
  File "/home/airflow/.local/lib/python3.8/site-packages/airflow/models/taskinstance.py", line 433, in _execute_task
    result = execute_callable(context=context, **execute_callable_kwargs)
  File "/home/airflow/.local/lib/python3.8/site-packages/airflow/operators/python.py", line 199, in execute
    return_value = self.execute_callable()
  File "/home/airflow/.local/lib/python3.8/site-packages/airflow/operators/python.py", line 216, in execute_callable
    return self.python_callable(*self.op_args, **self.op_kwargs)
  File "/opt/airflow/dags/extract_data.py", line 30, in extract_and_load_to_staging
    df = source_operator.get_data_to_pd(f"SELECT * FROM {table}")
  File "/opt/airflow/plugins/mysql_operator.py", line 15, in get_data_to_pd
    return self.mysqlhook.get_pandas_df(query)
  File "/home/airflow/.local/lib/python3.8/site-packages/airflow/providers/common/sql/hooks/sql.py", line 220, in get_pandas_df
    with closing(self.get_conn()) as conn:
  File "/home/airflow/.local/lib/python3.8/site-packages/airflow/providers/mysql/hooks/mysql.py", line 187, in get_conn
    conn = self.connection or self.get_connection(getattr(self, self.conn_name_attr))
  File "/home/airflow/.local/lib/python3.8/site-packages/airflow/hooks/base.py", line 82, in get_connection
    conn = Connection.get_connection_from_secrets(conn_id)
  File "/home/airflow/.local/lib/python3.8/site-packages/airflow/models/connection.py", line 479, in get_connection_from_secrets
    raise AirflowNotFoundException(f"The conn_id `{conn_id}` isn't defined")
airflow.exceptions.AirflowNotFoundException: The conn_id `mysql` isn't defined
[2025-05-06T14:42:19.984+0000] {taskinstance.py:1138} INFO - Marking task as FAILED. dag_id=e_commerce_dw_etl, task_id=extract.extract_and_load_to_staging, execution_date=20250309T000000, start_date=20250506T144219, end_date=20250506T144219
[2025-05-06T14:42:20.010+0000] {standard_task_runner.py:107} ERROR - Failed to execute job 137 for task extract.extract_and_load_to_staging (The conn_id `mysql` isn't defined; 1465)
[2025-05-06T14:42:20.052+0000] {local_task_job_runner.py:234} INFO - Task exited with return code 1
[2025-05-06T14:42:20.366+0000] {taskinstance.py:3280} INFO - 0 downstream tasks scheduled from follow-on schedule check
[2025-05-08T10:44:13.100+0000] {taskinstance.py:1956} INFO - Dependencies all met for dep_context=non-requeueable deps ti=<TaskInstance: e_commerce_dw_etl.extract.extract_and_load_to_staging scheduled__2025-03-09T00:00:00+00:00 [queued]>
[2025-05-08T10:44:13.116+0000] {taskinstance.py:1956} INFO - Dependencies all met for dep_context=requeueable deps ti=<TaskInstance: e_commerce_dw_etl.extract.extract_and_load_to_staging scheduled__2025-03-09T00:00:00+00:00 [queued]>
[2025-05-08T10:44:13.117+0000] {taskinstance.py:2170} INFO - Starting attempt 1 of 1
[2025-05-08T10:44:13.139+0000] {taskinstance.py:2191} INFO - Executing <Task(PythonOperator): extract.extract_and_load_to_staging> on 2025-03-09 00:00:00+00:00
[2025-05-08T10:44:13.145+0000] {standard_task_runner.py:60} INFO - Started process 663 to run task
[2025-05-08T10:44:13.147+0000] {standard_task_runner.py:87} INFO - Running: ['***', 'tasks', 'run', 'e_commerce_dw_etl', 'extract.extract_and_load_to_staging', 'scheduled__2025-03-09T00:00:00+00:00', '--job-id', '823', '--raw', '--subdir', 'DAGS_FOLDER/e_commerce_dw_dag.py', '--cfg-path', '/tmp/tmp8513xmiw']
[2025-05-08T10:44:13.149+0000] {standard_task_runner.py:88} INFO - Job 823: Subtask extract.extract_and_load_to_staging
[2025-05-08T10:44:13.365+0000] {logging_mixin.py:188} WARNING - /home/***/.local/lib/python3.8/site-packages/***/settings.py:194 DeprecationWarning: The sql_alchemy_conn option in [core] has been moved to the sql_alchemy_conn option in [database] - the old setting has been used, but please update your config.
[2025-05-08T10:44:13.413+0000] {task_command.py:423} INFO - Running <TaskInstance: e_commerce_dw_etl.extract.extract_and_load_to_staging scheduled__2025-03-09T00:00:00+00:00 [running]> on host 274dc1d73528
[2025-05-08T10:44:13.529+0000] {taskinstance.py:2480} INFO - Exporting env vars: AIRFLOW_CTX_DAG_OWNER='***' AIRFLOW_CTX_DAG_ID='e_commerce_dw_etl' AIRFLOW_CTX_TASK_ID='extract.extract_and_load_to_staging' AIRFLOW_CTX_EXECUTION_DATE='2025-03-09T00:00:00+00:00' AIRFLOW_CTX_TRY_NUMBER='1' AIRFLOW_CTX_DAG_RUN_ID='scheduled__2025-03-09T00:00:00+00:00'
[2025-05-08T10:44:13.542+0000] {mysql_operator.py:13} ERROR - Can't connect to mysql database
[2025-05-08T10:44:13.567+0000] {taskinstance.py:2698} ERROR - Task failed with exception
Traceback (most recent call last):
  File "/home/airflow/.local/lib/python3.8/site-packages/airflow/models/taskinstance.py", line 433, in _execute_task
    result = execute_callable(context=context, **execute_callable_kwargs)
  File "/home/airflow/.local/lib/python3.8/site-packages/airflow/operators/python.py", line 199, in execute
    return_value = self.execute_callable()
  File "/home/airflow/.local/lib/python3.8/site-packages/airflow/operators/python.py", line 216, in execute_callable
    return self.python_callable(*self.op_args, **self.op_kwargs)
  File "/opt/airflow/dags/extract_data.py", line 30, in extract_and_load_to_staging
    df = source_operator.get_data_to_pd(f"SELECT * FROM {table}")
  File "/opt/airflow/plugins/mysql_operator.py", line 15, in get_data_to_pd
    return self.mysqlhook.get_pandas_df(query)
  File "/home/airflow/.local/lib/python3.8/site-packages/airflow/providers/common/sql/hooks/sql.py", line 220, in get_pandas_df
    with closing(self.get_conn()) as conn:
  File "/home/airflow/.local/lib/python3.8/site-packages/airflow/providers/mysql/hooks/mysql.py", line 187, in get_conn
    conn = self.connection or self.get_connection(getattr(self, self.conn_name_attr))
  File "/home/airflow/.local/lib/python3.8/site-packages/airflow/hooks/base.py", line 82, in get_connection
    conn = Connection.get_connection_from_secrets(conn_id)
  File "/home/airflow/.local/lib/python3.8/site-packages/airflow/models/connection.py", line 479, in get_connection_from_secrets
    raise AirflowNotFoundException(f"The conn_id `{conn_id}` isn't defined")
airflow.exceptions.AirflowNotFoundException: The conn_id `mysql` isn't defined
[2025-05-08T10:44:13.581+0000] {taskinstance.py:1138} INFO - Marking task as FAILED. dag_id=e_commerce_dw_etl, task_id=extract.extract_and_load_to_staging, execution_date=20250309T000000, start_date=20250508T104413, end_date=20250508T104413
[2025-05-08T10:44:13.595+0000] {standard_task_runner.py:107} ERROR - Failed to execute job 823 for task extract.extract_and_load_to_staging (The conn_id `mysql` isn't defined; 663)
[2025-05-08T10:44:13.645+0000] {local_task_job_runner.py:234} INFO - Task exited with return code 1
[2025-05-08T10:44:13.884+0000] {taskinstance.py:3280} INFO - 0 downstream tasks scheduled from follow-on schedule check
[2025-05-08T11:06:49.206+0000] {taskinstance.py:1956} INFO - Dependencies all met for dep_context=non-requeueable deps ti=<TaskInstance: e_commerce_dw_etl.extract.extract_and_load_to_staging scheduled__2025-03-09T00:00:00+00:00 [queued]>
[2025-05-08T11:06:49.225+0000] {taskinstance.py:1956} INFO - Dependencies all met for dep_context=requeueable deps ti=<TaskInstance: e_commerce_dw_etl.extract.extract_and_load_to_staging scheduled__2025-03-09T00:00:00+00:00 [queued]>
[2025-05-08T11:06:49.226+0000] {taskinstance.py:2170} INFO - Starting attempt 1 of 1
[2025-05-08T11:06:49.255+0000] {taskinstance.py:2191} INFO - Executing <Task(PythonOperator): extract.extract_and_load_to_staging> on 2025-03-09 00:00:00+00:00
[2025-05-08T11:06:49.265+0000] {standard_task_runner.py:60} INFO - Started process 606 to run task
[2025-05-08T11:06:49.276+0000] {standard_task_runner.py:87} INFO - Running: ['***', 'tasks', 'run', 'e_commerce_dw_etl', 'extract.extract_and_load_to_staging', 'scheduled__2025-03-09T00:00:00+00:00', '--job-id', '1021', '--raw', '--subdir', 'DAGS_FOLDER/e_commerce_dw_dag.py', '--cfg-path', '/tmp/tmp1j94hypm']
[2025-05-08T11:06:49.280+0000] {standard_task_runner.py:88} INFO - Job 1021: Subtask extract.extract_and_load_to_staging
[2025-05-08T11:06:49.508+0000] {logging_mixin.py:188} WARNING - /home/***/.local/lib/python3.8/site-packages/***/settings.py:194 DeprecationWarning: The sql_alchemy_conn option in [core] has been moved to the sql_alchemy_conn option in [database] - the old setting has been used, but please update your config.
[2025-05-08T11:06:49.558+0000] {task_command.py:423} INFO - Running <TaskInstance: e_commerce_dw_etl.extract.extract_and_load_to_staging scheduled__2025-03-09T00:00:00+00:00 [running]> on host 14e98ede325e
[2025-05-08T11:06:49.660+0000] {taskinstance.py:2480} INFO - Exporting env vars: AIRFLOW_CTX_DAG_OWNER='***' AIRFLOW_CTX_DAG_ID='e_commerce_dw_etl' AIRFLOW_CTX_TASK_ID='extract.extract_and_load_to_staging' AIRFLOW_CTX_EXECUTION_DATE='2025-03-09T00:00:00+00:00' AIRFLOW_CTX_TRY_NUMBER='1' AIRFLOW_CTX_DAG_RUN_ID='scheduled__2025-03-09T00:00:00+00:00'
[2025-05-08T11:06:49.675+0000] {mysql_operator.py:13} ERROR - Can't connect to mysql database
[2025-05-08T11:06:49.695+0000] {taskinstance.py:2698} ERROR - Task failed with exception
Traceback (most recent call last):
  File "/home/airflow/.local/lib/python3.8/site-packages/airflow/models/taskinstance.py", line 433, in _execute_task
    result = execute_callable(context=context, **execute_callable_kwargs)
  File "/home/airflow/.local/lib/python3.8/site-packages/airflow/operators/python.py", line 199, in execute
    return_value = self.execute_callable()
  File "/home/airflow/.local/lib/python3.8/site-packages/airflow/operators/python.py", line 216, in execute_callable
    return self.python_callable(*self.op_args, **self.op_kwargs)
  File "/opt/airflow/dags/extract_data.py", line 30, in extract_and_load_to_staging
    df = source_operator.get_data_to_pd(f"SELECT * FROM {table}")
  File "/opt/airflow/plugins/mysql_operator.py", line 15, in get_data_to_pd
    return self.mysqlhook.get_pandas_df(query)
  File "/home/airflow/.local/lib/python3.8/site-packages/airflow/providers/common/sql/hooks/sql.py", line 220, in get_pandas_df
    with closing(self.get_conn()) as conn:
  File "/home/airflow/.local/lib/python3.8/site-packages/airflow/providers/mysql/hooks/mysql.py", line 187, in get_conn
    conn = self.connection or self.get_connection(getattr(self, self.conn_name_attr))
  File "/home/airflow/.local/lib/python3.8/site-packages/airflow/hooks/base.py", line 82, in get_connection
    conn = Connection.get_connection_from_secrets(conn_id)
  File "/home/airflow/.local/lib/python3.8/site-packages/airflow/models/connection.py", line 479, in get_connection_from_secrets
    raise AirflowNotFoundException(f"The conn_id `{conn_id}` isn't defined")
airflow.exceptions.AirflowNotFoundException: The conn_id `mysql` isn't defined
[2025-05-08T11:06:49.710+0000] {taskinstance.py:1138} INFO - Marking task as FAILED. dag_id=e_commerce_dw_etl, task_id=extract.extract_and_load_to_staging, execution_date=20250309T000000, start_date=20250508T110649, end_date=20250508T110649
[2025-05-08T11:06:49.725+0000] {standard_task_runner.py:107} ERROR - Failed to execute job 1021 for task extract.extract_and_load_to_staging (The conn_id `mysql` isn't defined; 606)
[2025-05-08T11:06:49.771+0000] {local_task_job_runner.py:234} INFO - Task exited with return code 1
[2025-05-08T11:06:49.986+0000] {taskinstance.py:3280} INFO - 0 downstream tasks scheduled from follow-on schedule check
[2025-05-08T11:09:48.272+0000] {taskinstance.py:1956} INFO - Dependencies all met for dep_context=non-requeueable deps ti=<TaskInstance: e_commerce_dw_etl.extract.extract_and_load_to_staging scheduled__2025-03-09T00:00:00+00:00 [queued]>
[2025-05-08T11:09:48.282+0000] {taskinstance.py:1956} INFO - Dependencies all met for dep_context=requeueable deps ti=<TaskInstance: e_commerce_dw_etl.extract.extract_and_load_to_staging scheduled__2025-03-09T00:00:00+00:00 [queued]>
[2025-05-08T11:09:48.283+0000] {taskinstance.py:2170} INFO - Starting attempt 1 of 1
[2025-05-08T11:09:48.300+0000] {taskinstance.py:2191} INFO - Executing <Task(PythonOperator): extract.extract_and_load_to_staging> on 2025-03-09 00:00:00+00:00
[2025-05-08T11:09:48.309+0000] {standard_task_runner.py:60} INFO - Started process 1117 to run task
[2025-05-08T11:09:48.316+0000] {standard_task_runner.py:87} INFO - Running: ['***', 'tasks', 'run', 'e_commerce_dw_etl', 'extract.extract_and_load_to_staging', 'scheduled__2025-03-09T00:00:00+00:00', '--job-id', '1216', '--raw', '--subdir', 'DAGS_FOLDER/e_commerce_dw_dag.py', '--cfg-path', '/tmp/tmp_zg2kisd']
[2025-05-08T11:09:48.320+0000] {standard_task_runner.py:88} INFO - Job 1216: Subtask extract.extract_and_load_to_staging
[2025-05-08T11:09:48.505+0000] {logging_mixin.py:188} WARNING - /home/***/.local/lib/python3.8/site-packages/***/settings.py:194 DeprecationWarning: The sql_alchemy_conn option in [core] has been moved to the sql_alchemy_conn option in [database] - the old setting has been used, but please update your config.
[2025-05-08T11:09:48.562+0000] {task_command.py:423} INFO - Running <TaskInstance: e_commerce_dw_etl.extract.extract_and_load_to_staging scheduled__2025-03-09T00:00:00+00:00 [running]> on host 14e98ede325e
[2025-05-08T11:09:48.693+0000] {taskinstance.py:2480} INFO - Exporting env vars: AIRFLOW_CTX_DAG_OWNER='***' AIRFLOW_CTX_DAG_ID='e_commerce_dw_etl' AIRFLOW_CTX_TASK_ID='extract.extract_and_load_to_staging' AIRFLOW_CTX_EXECUTION_DATE='2025-03-09T00:00:00+00:00' AIRFLOW_CTX_TRY_NUMBER='1' AIRFLOW_CTX_DAG_RUN_ID='scheduled__2025-03-09T00:00:00+00:00'
[2025-05-08T11:09:48.713+0000] {crypto.py:82} WARNING - empty cryptography key - values will not be stored encrypted.
[2025-05-08T11:09:48.715+0000] {connection.py:473} ERROR - Unable to retrieve connection from secrets backend (MetastoreBackend). Checking subsequent secrets backend.
Traceback (most recent call last):
  File "/home/airflow/.local/lib/python3.8/site-packages/airflow/models/connection.py", line 468, in get_connection_from_secrets
    conn = secrets_backend.get_connection(conn_id=conn_id)
  File "/home/airflow/.local/lib/python3.8/site-packages/airflow/utils/session.py", line 79, in wrapper
    return func(*args, session=session, **kwargs)
  File "/home/airflow/.local/lib/python3.8/site-packages/airflow/secrets/metastore.py", line 42, in get_connection
    return MetastoreBackend._fetch_connection(conn_id, session=session)
  File "/home/airflow/.local/lib/python3.8/site-packages/airflow/api_internal/internal_api_call.py", line 114, in wrapper
    return func(*args, **kwargs)
  File "/home/airflow/.local/lib/python3.8/site-packages/airflow/utils/session.py", line 76, in wrapper
    return func(*args, **kwargs)
  File "/home/airflow/.local/lib/python3.8/site-packages/airflow/secrets/metastore.py", line 73, in _fetch_connection
    conn = session.scalar(select(Connection).where(Connection.conn_id == conn_id).limit(1))
  File "/home/airflow/.local/lib/python3.8/site-packages/sqlalchemy/orm/session.py", line 1747, in scalar
    return self.execute(
  File "/home/airflow/.local/lib/python3.8/site-packages/sqlalchemy/engine/result.py", line 1276, in scalar
    return self._only_one_row(
  File "/home/airflow/.local/lib/python3.8/site-packages/sqlalchemy/engine/result.py", line 559, in _only_one_row
    row = onerow(hard_close=True)
  File "/home/airflow/.local/lib/python3.8/site-packages/sqlalchemy/engine/result.py", line 1801, in _fetchone_impl
    row = next(self.iterator, _NO_ROW)
  File "/home/airflow/.local/lib/python3.8/site-packages/sqlalchemy/orm/loading.py", line 151, in chunks
    rows = [proc(row) for row in fetch]
  File "/home/airflow/.local/lib/python3.8/site-packages/sqlalchemy/orm/loading.py", line 151, in <listcomp>
    rows = [proc(row) for row in fetch]
  File "/home/airflow/.local/lib/python3.8/site-packages/sqlalchemy/orm/loading.py", line 984, in _instance
    state.manager.dispatch.load(state, context)
  File "/home/airflow/.local/lib/python3.8/site-packages/sqlalchemy/event/attr.py", line 346, in __call__
    fn(*args, **kw)
  File "/home/airflow/.local/lib/python3.8/site-packages/sqlalchemy/orm/mapper.py", line 3702, in _event_on_load
    instrumenting_mapper._reconstructor(state.obj())
  File "/home/airflow/.local/lib/python3.8/site-packages/airflow/models/connection.py", line 174, in on_db_load
    if self.password:
  File "/home/airflow/.local/lib/python3.8/site-packages/sqlalchemy/orm/attributes.py", line 606, in __get__
    retval = self.descriptor.__get__(instance, owner)
  File "/home/airflow/.local/lib/python3.8/site-packages/airflow/models/connection.py", line 296, in get_password
    raise AirflowException(
airflow.exceptions.AirflowException: Can't decrypt encrypted password for login=***  FERNET_KEY configuration is missing
[2025-05-08T11:09:48.720+0000] {mysql_operator.py:13} ERROR - Can't connect to mysql database
[2025-05-08T11:09:48.730+0000] {connection.py:473} ERROR - Unable to retrieve connection from secrets backend (MetastoreBackend). Checking subsequent secrets backend.
Traceback (most recent call last):
  File "/home/airflow/.local/lib/python3.8/site-packages/airflow/models/connection.py", line 468, in get_connection_from_secrets
    conn = secrets_backend.get_connection(conn_id=conn_id)
  File "/home/airflow/.local/lib/python3.8/site-packages/airflow/utils/session.py", line 79, in wrapper
    return func(*args, session=session, **kwargs)
  File "/home/airflow/.local/lib/python3.8/site-packages/airflow/secrets/metastore.py", line 42, in get_connection
    return MetastoreBackend._fetch_connection(conn_id, session=session)
  File "/home/airflow/.local/lib/python3.8/site-packages/airflow/api_internal/internal_api_call.py", line 114, in wrapper
    return func(*args, **kwargs)
  File "/home/airflow/.local/lib/python3.8/site-packages/airflow/utils/session.py", line 76, in wrapper
    return func(*args, **kwargs)
  File "/home/airflow/.local/lib/python3.8/site-packages/airflow/secrets/metastore.py", line 73, in _fetch_connection
    conn = session.scalar(select(Connection).where(Connection.conn_id == conn_id).limit(1))
  File "/home/airflow/.local/lib/python3.8/site-packages/sqlalchemy/orm/session.py", line 1747, in scalar
    return self.execute(
  File "/home/airflow/.local/lib/python3.8/site-packages/sqlalchemy/engine/result.py", line 1276, in scalar
    return self._only_one_row(
  File "/home/airflow/.local/lib/python3.8/site-packages/sqlalchemy/engine/result.py", line 559, in _only_one_row
    row = onerow(hard_close=True)
  File "/home/airflow/.local/lib/python3.8/site-packages/sqlalchemy/engine/result.py", line 1801, in _fetchone_impl
    row = next(self.iterator, _NO_ROW)
  File "/home/airflow/.local/lib/python3.8/site-packages/sqlalchemy/orm/loading.py", line 151, in chunks
    rows = [proc(row) for row in fetch]
  File "/home/airflow/.local/lib/python3.8/site-packages/sqlalchemy/orm/loading.py", line 151, in <listcomp>
    rows = [proc(row) for row in fetch]
  File "/home/airflow/.local/lib/python3.8/site-packages/sqlalchemy/orm/loading.py", line 984, in _instance
    state.manager.dispatch.load(state, context)
  File "/home/airflow/.local/lib/python3.8/site-packages/sqlalchemy/event/attr.py", line 346, in __call__
    fn(*args, **kw)
  File "/home/airflow/.local/lib/python3.8/site-packages/sqlalchemy/orm/mapper.py", line 3702, in _event_on_load
    instrumenting_mapper._reconstructor(state.obj())
  File "/home/airflow/.local/lib/python3.8/site-packages/airflow/models/connection.py", line 174, in on_db_load
    if self.password:
  File "/home/airflow/.local/lib/python3.8/site-packages/sqlalchemy/orm/attributes.py", line 606, in __get__
    retval = self.descriptor.__get__(instance, owner)
  File "/home/airflow/.local/lib/python3.8/site-packages/airflow/models/connection.py", line 296, in get_password
    raise AirflowException(
airflow.exceptions.AirflowException: Can't decrypt encrypted password for login=***  FERNET_KEY configuration is missing
[2025-05-08T11:09:48.748+0000] {taskinstance.py:2698} ERROR - Task failed with exception
Traceback (most recent call last):
  File "/home/airflow/.local/lib/python3.8/site-packages/airflow/models/taskinstance.py", line 433, in _execute_task
    result = execute_callable(context=context, **execute_callable_kwargs)
  File "/home/airflow/.local/lib/python3.8/site-packages/airflow/operators/python.py", line 199, in execute
    return_value = self.execute_callable()
  File "/home/airflow/.local/lib/python3.8/site-packages/airflow/operators/python.py", line 216, in execute_callable
    return self.python_callable(*self.op_args, **self.op_kwargs)
  File "/opt/airflow/dags/extract_data.py", line 30, in extract_and_load_to_staging
    df = source_operator.get_data_to_pd(f"SELECT * FROM {table}")
  File "/opt/airflow/plugins/mysql_operator.py", line 15, in get_data_to_pd
    return self.mysqlhook.get_pandas_df(query)
  File "/home/airflow/.local/lib/python3.8/site-packages/airflow/providers/common/sql/hooks/sql.py", line 220, in get_pandas_df
    with closing(self.get_conn()) as conn:
  File "/home/airflow/.local/lib/python3.8/site-packages/airflow/providers/mysql/hooks/mysql.py", line 187, in get_conn
    conn = self.connection or self.get_connection(getattr(self, self.conn_name_attr))
  File "/home/airflow/.local/lib/python3.8/site-packages/airflow/hooks/base.py", line 82, in get_connection
    conn = Connection.get_connection_from_secrets(conn_id)
  File "/home/airflow/.local/lib/python3.8/site-packages/airflow/models/connection.py", line 479, in get_connection_from_secrets
    raise AirflowNotFoundException(f"The conn_id `{conn_id}` isn't defined")
airflow.exceptions.AirflowNotFoundException: The conn_id `mysql` isn't defined
[2025-05-08T11:09:48.770+0000] {taskinstance.py:1138} INFO - Marking task as FAILED. dag_id=e_commerce_dw_etl, task_id=extract.extract_and_load_to_staging, execution_date=20250309T000000, start_date=20250508T110948, end_date=20250508T110948
[2025-05-08T11:09:48.892+0000] {standard_task_runner.py:107} ERROR - Failed to execute job 1216 for task extract.extract_and_load_to_staging (The conn_id `mysql` isn't defined; 1117)
[2025-05-08T11:09:48.930+0000] {local_task_job_runner.py:234} INFO - Task exited with return code 1
[2025-05-08T11:09:49.217+0000] {taskinstance.py:3280} INFO - 0 downstream tasks scheduled from follow-on schedule check
[2025-05-08T11:15:37.660+0000] {taskinstance.py:1956} INFO - Dependencies all met for dep_context=non-requeueable deps ti=<TaskInstance: e_commerce_dw_etl.extract.extract_and_load_to_staging scheduled__2025-03-09T00:00:00+00:00 [queued]>
[2025-05-08T11:15:37.674+0000] {taskinstance.py:1956} INFO - Dependencies all met for dep_context=requeueable deps ti=<TaskInstance: e_commerce_dw_etl.extract.extract_and_load_to_staging scheduled__2025-03-09T00:00:00+00:00 [queued]>
[2025-05-08T11:15:37.675+0000] {taskinstance.py:2170} INFO - Starting attempt 1 of 1
[2025-05-08T11:15:37.706+0000] {taskinstance.py:2191} INFO - Executing <Task(PythonOperator): extract.extract_and_load_to_staging> on 2025-03-09 00:00:00+00:00
[2025-05-08T11:15:37.714+0000] {standard_task_runner.py:60} INFO - Started process 543 to run task
[2025-05-08T11:15:37.718+0000] {standard_task_runner.py:87} INFO - Running: ['***', 'tasks', 'run', 'e_commerce_dw_etl', 'extract.extract_and_load_to_staging', 'scheduled__2025-03-09T00:00:00+00:00', '--job-id', '1411', '--raw', '--subdir', 'DAGS_FOLDER/e_commerce_dw_dag.py', '--cfg-path', '/tmp/tmp5qy9r8x2']
[2025-05-08T11:15:37.723+0000] {standard_task_runner.py:88} INFO - Job 1411: Subtask extract.extract_and_load_to_staging
[2025-05-08T11:15:37.922+0000] {logging_mixin.py:188} WARNING - /home/***/.local/lib/python3.8/site-packages/***/settings.py:194 DeprecationWarning: The sql_alchemy_conn option in [core] has been moved to the sql_alchemy_conn option in [database] - the old setting has been used, but please update your config.
[2025-05-08T11:15:37.968+0000] {task_command.py:423} INFO - Running <TaskInstance: e_commerce_dw_etl.extract.extract_and_load_to_staging scheduled__2025-03-09T00:00:00+00:00 [running]> on host 3623a279d4d4
[2025-05-08T11:15:38.085+0000] {taskinstance.py:2480} INFO - Exporting env vars: AIRFLOW_CTX_DAG_OWNER='***' AIRFLOW_CTX_DAG_ID='e_commerce_dw_etl' AIRFLOW_CTX_TASK_ID='extract.extract_and_load_to_staging' AIRFLOW_CTX_EXECUTION_DATE='2025-03-09T00:00:00+00:00' AIRFLOW_CTX_TRY_NUMBER='1' AIRFLOW_CTX_DAG_RUN_ID='scheduled__2025-03-09T00:00:00+00:00'
[2025-05-08T11:15:38.100+0000] {crypto.py:82} WARNING - empty cryptography key - values will not be stored encrypted.
[2025-05-08T11:15:38.105+0000] {connection.py:473} ERROR - Unable to retrieve connection from secrets backend (MetastoreBackend). Checking subsequent secrets backend.
Traceback (most recent call last):
  File "/home/airflow/.local/lib/python3.8/site-packages/airflow/models/connection.py", line 468, in get_connection_from_secrets
    conn = secrets_backend.get_connection(conn_id=conn_id)
  File "/home/airflow/.local/lib/python3.8/site-packages/airflow/utils/session.py", line 79, in wrapper
    return func(*args, session=session, **kwargs)
  File "/home/airflow/.local/lib/python3.8/site-packages/airflow/secrets/metastore.py", line 42, in get_connection
    return MetastoreBackend._fetch_connection(conn_id, session=session)
  File "/home/airflow/.local/lib/python3.8/site-packages/airflow/api_internal/internal_api_call.py", line 114, in wrapper
    return func(*args, **kwargs)
  File "/home/airflow/.local/lib/python3.8/site-packages/airflow/utils/session.py", line 76, in wrapper
    return func(*args, **kwargs)
  File "/home/airflow/.local/lib/python3.8/site-packages/airflow/secrets/metastore.py", line 73, in _fetch_connection
    conn = session.scalar(select(Connection).where(Connection.conn_id == conn_id).limit(1))
  File "/home/airflow/.local/lib/python3.8/site-packages/sqlalchemy/orm/session.py", line 1747, in scalar
    return self.execute(
  File "/home/airflow/.local/lib/python3.8/site-packages/sqlalchemy/engine/result.py", line 1276, in scalar
    return self._only_one_row(
  File "/home/airflow/.local/lib/python3.8/site-packages/sqlalchemy/engine/result.py", line 559, in _only_one_row
    row = onerow(hard_close=True)
  File "/home/airflow/.local/lib/python3.8/site-packages/sqlalchemy/engine/result.py", line 1801, in _fetchone_impl
    row = next(self.iterator, _NO_ROW)
  File "/home/airflow/.local/lib/python3.8/site-packages/sqlalchemy/orm/loading.py", line 151, in chunks
    rows = [proc(row) for row in fetch]
  File "/home/airflow/.local/lib/python3.8/site-packages/sqlalchemy/orm/loading.py", line 151, in <listcomp>
    rows = [proc(row) for row in fetch]
  File "/home/airflow/.local/lib/python3.8/site-packages/sqlalchemy/orm/loading.py", line 984, in _instance
    state.manager.dispatch.load(state, context)
  File "/home/airflow/.local/lib/python3.8/site-packages/sqlalchemy/event/attr.py", line 346, in __call__
    fn(*args, **kw)
  File "/home/airflow/.local/lib/python3.8/site-packages/sqlalchemy/orm/mapper.py", line 3702, in _event_on_load
    instrumenting_mapper._reconstructor(state.obj())
  File "/home/airflow/.local/lib/python3.8/site-packages/airflow/models/connection.py", line 174, in on_db_load
    if self.password:
  File "/home/airflow/.local/lib/python3.8/site-packages/sqlalchemy/orm/attributes.py", line 606, in __get__
    retval = self.descriptor.__get__(instance, owner)
  File "/home/airflow/.local/lib/python3.8/site-packages/airflow/models/connection.py", line 296, in get_password
    raise AirflowException(
airflow.exceptions.AirflowException: Can't decrypt encrypted password for login=***  FERNET_KEY configuration is missing
[2025-05-08T11:15:38.112+0000] {mysql_operator.py:13} ERROR - Can't connect to mysql database
[2025-05-08T11:15:38.123+0000] {connection.py:473} ERROR - Unable to retrieve connection from secrets backend (MetastoreBackend). Checking subsequent secrets backend.
Traceback (most recent call last):
  File "/home/airflow/.local/lib/python3.8/site-packages/airflow/models/connection.py", line 468, in get_connection_from_secrets
    conn = secrets_backend.get_connection(conn_id=conn_id)
  File "/home/airflow/.local/lib/python3.8/site-packages/airflow/utils/session.py", line 79, in wrapper
    return func(*args, session=session, **kwargs)
  File "/home/airflow/.local/lib/python3.8/site-packages/airflow/secrets/metastore.py", line 42, in get_connection
    return MetastoreBackend._fetch_connection(conn_id, session=session)
  File "/home/airflow/.local/lib/python3.8/site-packages/airflow/api_internal/internal_api_call.py", line 114, in wrapper
    return func(*args, **kwargs)
  File "/home/airflow/.local/lib/python3.8/site-packages/airflow/utils/session.py", line 76, in wrapper
    return func(*args, **kwargs)
  File "/home/airflow/.local/lib/python3.8/site-packages/airflow/secrets/metastore.py", line 73, in _fetch_connection
    conn = session.scalar(select(Connection).where(Connection.conn_id == conn_id).limit(1))
  File "/home/airflow/.local/lib/python3.8/site-packages/sqlalchemy/orm/session.py", line 1747, in scalar
    return self.execute(
  File "/home/airflow/.local/lib/python3.8/site-packages/sqlalchemy/engine/result.py", line 1276, in scalar
    return self._only_one_row(
  File "/home/airflow/.local/lib/python3.8/site-packages/sqlalchemy/engine/result.py", line 559, in _only_one_row
    row = onerow(hard_close=True)
  File "/home/airflow/.local/lib/python3.8/site-packages/sqlalchemy/engine/result.py", line 1801, in _fetchone_impl
    row = next(self.iterator, _NO_ROW)
  File "/home/airflow/.local/lib/python3.8/site-packages/sqlalchemy/orm/loading.py", line 151, in chunks
    rows = [proc(row) for row in fetch]
  File "/home/airflow/.local/lib/python3.8/site-packages/sqlalchemy/orm/loading.py", line 151, in <listcomp>
    rows = [proc(row) for row in fetch]
  File "/home/airflow/.local/lib/python3.8/site-packages/sqlalchemy/orm/loading.py", line 984, in _instance
    state.manager.dispatch.load(state, context)
  File "/home/airflow/.local/lib/python3.8/site-packages/sqlalchemy/event/attr.py", line 346, in __call__
    fn(*args, **kw)
  File "/home/airflow/.local/lib/python3.8/site-packages/sqlalchemy/orm/mapper.py", line 3702, in _event_on_load
    instrumenting_mapper._reconstructor(state.obj())
  File "/home/airflow/.local/lib/python3.8/site-packages/airflow/models/connection.py", line 174, in on_db_load
    if self.password:
  File "/home/airflow/.local/lib/python3.8/site-packages/sqlalchemy/orm/attributes.py", line 606, in __get__
    retval = self.descriptor.__get__(instance, owner)
  File "/home/airflow/.local/lib/python3.8/site-packages/airflow/models/connection.py", line 296, in get_password
    raise AirflowException(
airflow.exceptions.AirflowException: Can't decrypt encrypted password for login=***  FERNET_KEY configuration is missing
[2025-05-08T11:15:38.141+0000] {taskinstance.py:2698} ERROR - Task failed with exception
Traceback (most recent call last):
  File "/home/airflow/.local/lib/python3.8/site-packages/airflow/models/taskinstance.py", line 433, in _execute_task
    result = execute_callable(context=context, **execute_callable_kwargs)
  File "/home/airflow/.local/lib/python3.8/site-packages/airflow/operators/python.py", line 199, in execute
    return_value = self.execute_callable()
  File "/home/airflow/.local/lib/python3.8/site-packages/airflow/operators/python.py", line 216, in execute_callable
    return self.python_callable(*self.op_args, **self.op_kwargs)
  File "/opt/airflow/dags/extract_data.py", line 30, in extract_and_load_to_staging
    df = source_operator.get_data_to_pd(f"SELECT * FROM {table}")
  File "/opt/airflow/plugins/mysql_operator.py", line 15, in get_data_to_pd
    return self.mysqlhook.get_pandas_df(query)
  File "/home/airflow/.local/lib/python3.8/site-packages/airflow/providers/common/sql/hooks/sql.py", line 220, in get_pandas_df
    with closing(self.get_conn()) as conn:
  File "/home/airflow/.local/lib/python3.8/site-packages/airflow/providers/mysql/hooks/mysql.py", line 187, in get_conn
    conn = self.connection or self.get_connection(getattr(self, self.conn_name_attr))
  File "/home/airflow/.local/lib/python3.8/site-packages/airflow/hooks/base.py", line 82, in get_connection
    conn = Connection.get_connection_from_secrets(conn_id)
  File "/home/airflow/.local/lib/python3.8/site-packages/airflow/models/connection.py", line 479, in get_connection_from_secrets
    raise AirflowNotFoundException(f"The conn_id `{conn_id}` isn't defined")
airflow.exceptions.AirflowNotFoundException: The conn_id `mysql` isn't defined
[2025-05-08T11:15:38.155+0000] {taskinstance.py:1138} INFO - Marking task as FAILED. dag_id=e_commerce_dw_etl, task_id=extract.extract_and_load_to_staging, execution_date=20250309T000000, start_date=20250508T111537, end_date=20250508T111538
[2025-05-08T11:15:38.250+0000] {standard_task_runner.py:107} ERROR - Failed to execute job 1411 for task extract.extract_and_load_to_staging (The conn_id `mysql` isn't defined; 543)
[2025-05-08T11:15:38.293+0000] {local_task_job_runner.py:234} INFO - Task exited with return code 1
[2025-05-08T11:15:38.560+0000] {taskinstance.py:3280} INFO - 0 downstream tasks scheduled from follow-on schedule check
[2025-05-08T11:18:24.627+0000] {taskinstance.py:1956} INFO - Dependencies all met for dep_context=non-requeueable deps ti=<TaskInstance: e_commerce_dw_etl.extract.extract_and_load_to_staging scheduled__2025-03-09T00:00:00+00:00 [queued]>
[2025-05-08T11:18:24.642+0000] {taskinstance.py:1956} INFO - Dependencies all met for dep_context=requeueable deps ti=<TaskInstance: e_commerce_dw_etl.extract.extract_and_load_to_staging scheduled__2025-03-09T00:00:00+00:00 [queued]>
[2025-05-08T11:18:24.643+0000] {taskinstance.py:2170} INFO - Starting attempt 1 of 1
[2025-05-08T11:18:24.717+0000] {taskinstance.py:2191} INFO - Executing <Task(PythonOperator): extract.extract_and_load_to_staging> on 2025-03-09 00:00:00+00:00
[2025-05-08T11:18:24.724+0000] {standard_task_runner.py:60} INFO - Started process 842 to run task
[2025-05-08T11:18:24.732+0000] {standard_task_runner.py:87} INFO - Running: ['***', 'tasks', 'run', 'e_commerce_dw_etl', 'extract.extract_and_load_to_staging', 'scheduled__2025-03-09T00:00:00+00:00', '--job-id', '1511', '--raw', '--subdir', 'DAGS_FOLDER/e_commerce_dw_dag.py', '--cfg-path', '/tmp/tmp3jf8hoa1']
[2025-05-08T11:18:24.735+0000] {standard_task_runner.py:88} INFO - Job 1511: Subtask extract.extract_and_load_to_staging
[2025-05-08T11:18:24.912+0000] {logging_mixin.py:188} WARNING - /home/***/.local/lib/python3.8/site-packages/***/settings.py:194 DeprecationWarning: The sql_alchemy_conn option in [core] has been moved to the sql_alchemy_conn option in [database] - the old setting has been used, but please update your config.
[2025-05-08T11:18:24.949+0000] {task_command.py:423} INFO - Running <TaskInstance: e_commerce_dw_etl.extract.extract_and_load_to_staging scheduled__2025-03-09T00:00:00+00:00 [running]> on host 3623a279d4d4
[2025-05-08T11:18:25.035+0000] {taskinstance.py:2480} INFO - Exporting env vars: AIRFLOW_CTX_DAG_OWNER='***' AIRFLOW_CTX_DAG_ID='e_commerce_dw_etl' AIRFLOW_CTX_TASK_ID='extract.extract_and_load_to_staging' AIRFLOW_CTX_EXECUTION_DATE='2025-03-09T00:00:00+00:00' AIRFLOW_CTX_TRY_NUMBER='1' AIRFLOW_CTX_DAG_RUN_ID='scheduled__2025-03-09T00:00:00+00:00'
[2025-05-08T11:18:25.045+0000] {crypto.py:82} WARNING - empty cryptography key - values will not be stored encrypted.
[2025-05-08T11:18:25.047+0000] {connection.py:473} ERROR - Unable to retrieve connection from secrets backend (MetastoreBackend). Checking subsequent secrets backend.
Traceback (most recent call last):
  File "/home/airflow/.local/lib/python3.8/site-packages/airflow/models/connection.py", line 468, in get_connection_from_secrets
    conn = secrets_backend.get_connection(conn_id=conn_id)
  File "/home/airflow/.local/lib/python3.8/site-packages/airflow/utils/session.py", line 79, in wrapper
    return func(*args, session=session, **kwargs)
  File "/home/airflow/.local/lib/python3.8/site-packages/airflow/secrets/metastore.py", line 42, in get_connection
    return MetastoreBackend._fetch_connection(conn_id, session=session)
  File "/home/airflow/.local/lib/python3.8/site-packages/airflow/api_internal/internal_api_call.py", line 114, in wrapper
    return func(*args, **kwargs)
  File "/home/airflow/.local/lib/python3.8/site-packages/airflow/utils/session.py", line 76, in wrapper
    return func(*args, **kwargs)
  File "/home/airflow/.local/lib/python3.8/site-packages/airflow/secrets/metastore.py", line 73, in _fetch_connection
    conn = session.scalar(select(Connection).where(Connection.conn_id == conn_id).limit(1))
  File "/home/airflow/.local/lib/python3.8/site-packages/sqlalchemy/orm/session.py", line 1747, in scalar
    return self.execute(
  File "/home/airflow/.local/lib/python3.8/site-packages/sqlalchemy/engine/result.py", line 1276, in scalar
    return self._only_one_row(
  File "/home/airflow/.local/lib/python3.8/site-packages/sqlalchemy/engine/result.py", line 559, in _only_one_row
    row = onerow(hard_close=True)
  File "/home/airflow/.local/lib/python3.8/site-packages/sqlalchemy/engine/result.py", line 1801, in _fetchone_impl
    row = next(self.iterator, _NO_ROW)
  File "/home/airflow/.local/lib/python3.8/site-packages/sqlalchemy/orm/loading.py", line 151, in chunks
    rows = [proc(row) for row in fetch]
  File "/home/airflow/.local/lib/python3.8/site-packages/sqlalchemy/orm/loading.py", line 151, in <listcomp>
    rows = [proc(row) for row in fetch]
  File "/home/airflow/.local/lib/python3.8/site-packages/sqlalchemy/orm/loading.py", line 984, in _instance
    state.manager.dispatch.load(state, context)
  File "/home/airflow/.local/lib/python3.8/site-packages/sqlalchemy/event/attr.py", line 346, in __call__
    fn(*args, **kw)
  File "/home/airflow/.local/lib/python3.8/site-packages/sqlalchemy/orm/mapper.py", line 3702, in _event_on_load
    instrumenting_mapper._reconstructor(state.obj())
  File "/home/airflow/.local/lib/python3.8/site-packages/airflow/models/connection.py", line 174, in on_db_load
    if self.password:
  File "/home/airflow/.local/lib/python3.8/site-packages/sqlalchemy/orm/attributes.py", line 606, in __get__
    retval = self.descriptor.__get__(instance, owner)
  File "/home/airflow/.local/lib/python3.8/site-packages/airflow/models/connection.py", line 296, in get_password
    raise AirflowException(
airflow.exceptions.AirflowException: Can't decrypt encrypted password for login=***  FERNET_KEY configuration is missing
[2025-05-08T11:18:25.050+0000] {mysql_operator.py:13} ERROR - Can't connect to mysql database
[2025-05-08T11:18:25.059+0000] {connection.py:473} ERROR - Unable to retrieve connection from secrets backend (MetastoreBackend). Checking subsequent secrets backend.
Traceback (most recent call last):
  File "/home/airflow/.local/lib/python3.8/site-packages/airflow/models/connection.py", line 468, in get_connection_from_secrets
    conn = secrets_backend.get_connection(conn_id=conn_id)
  File "/home/airflow/.local/lib/python3.8/site-packages/airflow/utils/session.py", line 79, in wrapper
    return func(*args, session=session, **kwargs)
  File "/home/airflow/.local/lib/python3.8/site-packages/airflow/secrets/metastore.py", line 42, in get_connection
    return MetastoreBackend._fetch_connection(conn_id, session=session)
  File "/home/airflow/.local/lib/python3.8/site-packages/airflow/api_internal/internal_api_call.py", line 114, in wrapper
    return func(*args, **kwargs)
  File "/home/airflow/.local/lib/python3.8/site-packages/airflow/utils/session.py", line 76, in wrapper
    return func(*args, **kwargs)
  File "/home/airflow/.local/lib/python3.8/site-packages/airflow/secrets/metastore.py", line 73, in _fetch_connection
    conn = session.scalar(select(Connection).where(Connection.conn_id == conn_id).limit(1))
  File "/home/airflow/.local/lib/python3.8/site-packages/sqlalchemy/orm/session.py", line 1747, in scalar
    return self.execute(
  File "/home/airflow/.local/lib/python3.8/site-packages/sqlalchemy/engine/result.py", line 1276, in scalar
    return self._only_one_row(
  File "/home/airflow/.local/lib/python3.8/site-packages/sqlalchemy/engine/result.py", line 559, in _only_one_row
    row = onerow(hard_close=True)
  File "/home/airflow/.local/lib/python3.8/site-packages/sqlalchemy/engine/result.py", line 1801, in _fetchone_impl
    row = next(self.iterator, _NO_ROW)
  File "/home/airflow/.local/lib/python3.8/site-packages/sqlalchemy/orm/loading.py", line 151, in chunks
    rows = [proc(row) for row in fetch]
  File "/home/airflow/.local/lib/python3.8/site-packages/sqlalchemy/orm/loading.py", line 151, in <listcomp>
    rows = [proc(row) for row in fetch]
  File "/home/airflow/.local/lib/python3.8/site-packages/sqlalchemy/orm/loading.py", line 984, in _instance
    state.manager.dispatch.load(state, context)
  File "/home/airflow/.local/lib/python3.8/site-packages/sqlalchemy/event/attr.py", line 346, in __call__
    fn(*args, **kw)
  File "/home/airflow/.local/lib/python3.8/site-packages/sqlalchemy/orm/mapper.py", line 3702, in _event_on_load
    instrumenting_mapper._reconstructor(state.obj())
  File "/home/airflow/.local/lib/python3.8/site-packages/airflow/models/connection.py", line 174, in on_db_load
    if self.password:
  File "/home/airflow/.local/lib/python3.8/site-packages/sqlalchemy/orm/attributes.py", line 606, in __get__
    retval = self.descriptor.__get__(instance, owner)
  File "/home/airflow/.local/lib/python3.8/site-packages/airflow/models/connection.py", line 296, in get_password
    raise AirflowException(
airflow.exceptions.AirflowException: Can't decrypt encrypted password for login=***  FERNET_KEY configuration is missing
[2025-05-08T11:18:25.069+0000] {taskinstance.py:2698} ERROR - Task failed with exception
Traceback (most recent call last):
  File "/home/airflow/.local/lib/python3.8/site-packages/airflow/models/taskinstance.py", line 433, in _execute_task
    result = execute_callable(context=context, **execute_callable_kwargs)
  File "/home/airflow/.local/lib/python3.8/site-packages/airflow/operators/python.py", line 199, in execute
    return_value = self.execute_callable()
  File "/home/airflow/.local/lib/python3.8/site-packages/airflow/operators/python.py", line 216, in execute_callable
    return self.python_callable(*self.op_args, **self.op_kwargs)
  File "/opt/airflow/dags/extract_data.py", line 30, in extract_and_load_to_staging
    df = source_operator.get_data_to_pd(f"SELECT * FROM {table}")
  File "/opt/airflow/plugins/mysql_operator.py", line 15, in get_data_to_pd
    return self.mysqlhook.get_pandas_df(query)
  File "/home/airflow/.local/lib/python3.8/site-packages/airflow/providers/common/sql/hooks/sql.py", line 220, in get_pandas_df
    with closing(self.get_conn()) as conn:
  File "/home/airflow/.local/lib/python3.8/site-packages/airflow/providers/mysql/hooks/mysql.py", line 187, in get_conn
    conn = self.connection or self.get_connection(getattr(self, self.conn_name_attr))
  File "/home/airflow/.local/lib/python3.8/site-packages/airflow/hooks/base.py", line 82, in get_connection
    conn = Connection.get_connection_from_secrets(conn_id)
  File "/home/airflow/.local/lib/python3.8/site-packages/airflow/models/connection.py", line 479, in get_connection_from_secrets
    raise AirflowNotFoundException(f"The conn_id `{conn_id}` isn't defined")
airflow.exceptions.AirflowNotFoundException: The conn_id `mysql` isn't defined
[2025-05-08T11:18:25.080+0000] {taskinstance.py:1138} INFO - Marking task as FAILED. dag_id=e_commerce_dw_etl, task_id=extract.extract_and_load_to_staging, execution_date=20250309T000000, start_date=20250508T111824, end_date=20250508T111825
[2025-05-08T11:18:25.090+0000] {standard_task_runner.py:107} ERROR - Failed to execute job 1511 for task extract.extract_and_load_to_staging (The conn_id `mysql` isn't defined; 842)
[2025-05-08T11:18:25.104+0000] {local_task_job_runner.py:234} INFO - Task exited with return code 1
[2025-05-08T11:18:25.246+0000] {taskinstance.py:3280} INFO - 0 downstream tasks scheduled from follow-on schedule check
[2025-05-08T11:20:52.815+0000] {taskinstance.py:1956} INFO - Dependencies all met for dep_context=non-requeueable deps ti=<TaskInstance: e_commerce_dw_etl.extract.extract_and_load_to_staging scheduled__2025-03-09T00:00:00+00:00 [queued]>
[2025-05-08T11:20:52.831+0000] {taskinstance.py:1956} INFO - Dependencies all met for dep_context=requeueable deps ti=<TaskInstance: e_commerce_dw_etl.extract.extract_and_load_to_staging scheduled__2025-03-09T00:00:00+00:00 [queued]>
[2025-05-08T11:20:52.832+0000] {taskinstance.py:2170} INFO - Starting attempt 1 of 1
[2025-05-08T11:20:52.869+0000] {taskinstance.py:2191} INFO - Executing <Task(PythonOperator): extract.extract_and_load_to_staging> on 2025-03-09 00:00:00+00:00
[2025-05-08T11:20:52.886+0000] {standard_task_runner.py:60} INFO - Started process 1333 to run task
[2025-05-08T11:20:52.900+0000] {standard_task_runner.py:87} INFO - Running: ['***', 'tasks', 'run', 'e_commerce_dw_etl', 'extract.extract_and_load_to_staging', 'scheduled__2025-03-09T00:00:00+00:00', '--job-id', '1706', '--raw', '--subdir', 'DAGS_FOLDER/e_commerce_dw_dag.py', '--cfg-path', '/tmp/tmpk7zj85z8']
[2025-05-08T11:20:52.906+0000] {standard_task_runner.py:88} INFO - Job 1706: Subtask extract.extract_and_load_to_staging
[2025-05-08T11:20:53.175+0000] {logging_mixin.py:188} WARNING - /home/***/.local/lib/python3.8/site-packages/***/settings.py:194 DeprecationWarning: The sql_alchemy_conn option in [core] has been moved to the sql_alchemy_conn option in [database] - the old setting has been used, but please update your config.
[2025-05-08T11:20:53.235+0000] {task_command.py:423} INFO - Running <TaskInstance: e_commerce_dw_etl.extract.extract_and_load_to_staging scheduled__2025-03-09T00:00:00+00:00 [running]> on host 3623a279d4d4
[2025-05-08T11:20:53.541+0000] {taskinstance.py:2480} INFO - Exporting env vars: AIRFLOW_CTX_DAG_OWNER='***' AIRFLOW_CTX_DAG_ID='e_commerce_dw_etl' AIRFLOW_CTX_TASK_ID='extract.extract_and_load_to_staging' AIRFLOW_CTX_EXECUTION_DATE='2025-03-09T00:00:00+00:00' AIRFLOW_CTX_TRY_NUMBER='1' AIRFLOW_CTX_DAG_RUN_ID='scheduled__2025-03-09T00:00:00+00:00'
[2025-05-08T11:20:53.552+0000] {crypto.py:82} WARNING - empty cryptography key - values will not be stored encrypted.
[2025-05-08T11:20:53.554+0000] {connection.py:473} ERROR - Unable to retrieve connection from secrets backend (MetastoreBackend). Checking subsequent secrets backend.
Traceback (most recent call last):
  File "/home/airflow/.local/lib/python3.8/site-packages/airflow/models/connection.py", line 468, in get_connection_from_secrets
    conn = secrets_backend.get_connection(conn_id=conn_id)
  File "/home/airflow/.local/lib/python3.8/site-packages/airflow/utils/session.py", line 79, in wrapper
    return func(*args, session=session, **kwargs)
  File "/home/airflow/.local/lib/python3.8/site-packages/airflow/secrets/metastore.py", line 42, in get_connection
    return MetastoreBackend._fetch_connection(conn_id, session=session)
  File "/home/airflow/.local/lib/python3.8/site-packages/airflow/api_internal/internal_api_call.py", line 114, in wrapper
    return func(*args, **kwargs)
  File "/home/airflow/.local/lib/python3.8/site-packages/airflow/utils/session.py", line 76, in wrapper
    return func(*args, **kwargs)
  File "/home/airflow/.local/lib/python3.8/site-packages/airflow/secrets/metastore.py", line 73, in _fetch_connection
    conn = session.scalar(select(Connection).where(Connection.conn_id == conn_id).limit(1))
  File "/home/airflow/.local/lib/python3.8/site-packages/sqlalchemy/orm/session.py", line 1747, in scalar
    return self.execute(
  File "/home/airflow/.local/lib/python3.8/site-packages/sqlalchemy/engine/result.py", line 1276, in scalar
    return self._only_one_row(
  File "/home/airflow/.local/lib/python3.8/site-packages/sqlalchemy/engine/result.py", line 559, in _only_one_row
    row = onerow(hard_close=True)
  File "/home/airflow/.local/lib/python3.8/site-packages/sqlalchemy/engine/result.py", line 1801, in _fetchone_impl
    row = next(self.iterator, _NO_ROW)
  File "/home/airflow/.local/lib/python3.8/site-packages/sqlalchemy/orm/loading.py", line 151, in chunks
    rows = [proc(row) for row in fetch]
  File "/home/airflow/.local/lib/python3.8/site-packages/sqlalchemy/orm/loading.py", line 151, in <listcomp>
    rows = [proc(row) for row in fetch]
  File "/home/airflow/.local/lib/python3.8/site-packages/sqlalchemy/orm/loading.py", line 984, in _instance
    state.manager.dispatch.load(state, context)
  File "/home/airflow/.local/lib/python3.8/site-packages/sqlalchemy/event/attr.py", line 346, in __call__
    fn(*args, **kw)
  File "/home/airflow/.local/lib/python3.8/site-packages/sqlalchemy/orm/mapper.py", line 3702, in _event_on_load
    instrumenting_mapper._reconstructor(state.obj())
  File "/home/airflow/.local/lib/python3.8/site-packages/airflow/models/connection.py", line 174, in on_db_load
    if self.password:
  File "/home/airflow/.local/lib/python3.8/site-packages/sqlalchemy/orm/attributes.py", line 606, in __get__
    retval = self.descriptor.__get__(instance, owner)
  File "/home/airflow/.local/lib/python3.8/site-packages/airflow/models/connection.py", line 296, in get_password
    raise AirflowException(
airflow.exceptions.AirflowException: Can't decrypt encrypted password for login=***  FERNET_KEY configuration is missing
[2025-05-08T11:20:53.562+0000] {mysql_operator.py:13} ERROR - Can't connect to mysql database
[2025-05-08T11:20:53.573+0000] {connection.py:473} ERROR - Unable to retrieve connection from secrets backend (MetastoreBackend). Checking subsequent secrets backend.
Traceback (most recent call last):
  File "/home/airflow/.local/lib/python3.8/site-packages/airflow/models/connection.py", line 468, in get_connection_from_secrets
    conn = secrets_backend.get_connection(conn_id=conn_id)
  File "/home/airflow/.local/lib/python3.8/site-packages/airflow/utils/session.py", line 79, in wrapper
    return func(*args, session=session, **kwargs)
  File "/home/airflow/.local/lib/python3.8/site-packages/airflow/secrets/metastore.py", line 42, in get_connection
    return MetastoreBackend._fetch_connection(conn_id, session=session)
  File "/home/airflow/.local/lib/python3.8/site-packages/airflow/api_internal/internal_api_call.py", line 114, in wrapper
    return func(*args, **kwargs)
  File "/home/airflow/.local/lib/python3.8/site-packages/airflow/utils/session.py", line 76, in wrapper
    return func(*args, **kwargs)
  File "/home/airflow/.local/lib/python3.8/site-packages/airflow/secrets/metastore.py", line 73, in _fetch_connection
    conn = session.scalar(select(Connection).where(Connection.conn_id == conn_id).limit(1))
  File "/home/airflow/.local/lib/python3.8/site-packages/sqlalchemy/orm/session.py", line 1747, in scalar
    return self.execute(
  File "/home/airflow/.local/lib/python3.8/site-packages/sqlalchemy/engine/result.py", line 1276, in scalar
    return self._only_one_row(
  File "/home/airflow/.local/lib/python3.8/site-packages/sqlalchemy/engine/result.py", line 559, in _only_one_row
    row = onerow(hard_close=True)
  File "/home/airflow/.local/lib/python3.8/site-packages/sqlalchemy/engine/result.py", line 1801, in _fetchone_impl
    row = next(self.iterator, _NO_ROW)
  File "/home/airflow/.local/lib/python3.8/site-packages/sqlalchemy/orm/loading.py", line 151, in chunks
    rows = [proc(row) for row in fetch]
  File "/home/airflow/.local/lib/python3.8/site-packages/sqlalchemy/orm/loading.py", line 151, in <listcomp>
    rows = [proc(row) for row in fetch]
  File "/home/airflow/.local/lib/python3.8/site-packages/sqlalchemy/orm/loading.py", line 984, in _instance
    state.manager.dispatch.load(state, context)
  File "/home/airflow/.local/lib/python3.8/site-packages/sqlalchemy/event/attr.py", line 346, in __call__
    fn(*args, **kw)
  File "/home/airflow/.local/lib/python3.8/site-packages/sqlalchemy/orm/mapper.py", line 3702, in _event_on_load
    instrumenting_mapper._reconstructor(state.obj())
  File "/home/airflow/.local/lib/python3.8/site-packages/airflow/models/connection.py", line 174, in on_db_load
    if self.password:
  File "/home/airflow/.local/lib/python3.8/site-packages/sqlalchemy/orm/attributes.py", line 606, in __get__
    retval = self.descriptor.__get__(instance, owner)
  File "/home/airflow/.local/lib/python3.8/site-packages/airflow/models/connection.py", line 296, in get_password
    raise AirflowException(
airflow.exceptions.AirflowException: Can't decrypt encrypted password for login=***  FERNET_KEY configuration is missing
[2025-05-08T11:20:53.586+0000] {taskinstance.py:2698} ERROR - Task failed with exception
Traceback (most recent call last):
  File "/home/airflow/.local/lib/python3.8/site-packages/airflow/models/taskinstance.py", line 433, in _execute_task
    result = execute_callable(context=context, **execute_callable_kwargs)
  File "/home/airflow/.local/lib/python3.8/site-packages/airflow/operators/python.py", line 199, in execute
    return_value = self.execute_callable()
  File "/home/airflow/.local/lib/python3.8/site-packages/airflow/operators/python.py", line 216, in execute_callable
    return self.python_callable(*self.op_args, **self.op_kwargs)
  File "/opt/airflow/dags/extract_data.py", line 30, in extract_and_load_to_staging
    df = source_operator.get_data_to_pd(f"SELECT * FROM {table}")
  File "/opt/airflow/plugins/mysql_operator.py", line 15, in get_data_to_pd
    return self.mysqlhook.get_pandas_df(query)
  File "/home/airflow/.local/lib/python3.8/site-packages/airflow/providers/common/sql/hooks/sql.py", line 220, in get_pandas_df
    with closing(self.get_conn()) as conn:
  File "/home/airflow/.local/lib/python3.8/site-packages/airflow/providers/mysql/hooks/mysql.py", line 187, in get_conn
    conn = self.connection or self.get_connection(getattr(self, self.conn_name_attr))
  File "/home/airflow/.local/lib/python3.8/site-packages/airflow/hooks/base.py", line 82, in get_connection
    conn = Connection.get_connection_from_secrets(conn_id)
  File "/home/airflow/.local/lib/python3.8/site-packages/airflow/models/connection.py", line 479, in get_connection_from_secrets
    raise AirflowNotFoundException(f"The conn_id `{conn_id}` isn't defined")
airflow.exceptions.AirflowNotFoundException: The conn_id `mysql` isn't defined
[2025-05-08T11:20:53.601+0000] {taskinstance.py:1138} INFO - Marking task as FAILED. dag_id=e_commerce_dw_etl, task_id=extract.extract_and_load_to_staging, execution_date=20250309T000000, start_date=20250508T112052, end_date=20250508T112053
[2025-05-08T11:20:53.623+0000] {standard_task_runner.py:107} ERROR - Failed to execute job 1706 for task extract.extract_and_load_to_staging (The conn_id `mysql` isn't defined; 1333)
[2025-05-08T11:20:53.638+0000] {local_task_job_runner.py:234} INFO - Task exited with return code 1
[2025-05-08T11:20:53.876+0000] {taskinstance.py:3280} INFO - 0 downstream tasks scheduled from follow-on schedule check
