[2025-05-06T14:41:56.689+0000] {taskinstance.py:1956} INFO - Dependencies all met for dep_context=non-requeueable deps ti=<TaskInstance: e_commerce_dw_etl.extract.extract_and_load_to_staging scheduled__2025-01-23T00:00:00+00:00 [queued]>
[2025-05-06T14:41:56.703+0000] {taskinstance.py:1956} INFO - Dependencies all met for dep_context=requeueable deps ti=<TaskInstance: e_commerce_dw_etl.extract.extract_and_load_to_staging scheduled__2025-01-23T00:00:00+00:00 [queued]>
[2025-05-06T14:41:56.704+0000] {taskinstance.py:2170} INFO - Starting attempt 1 of 1
[2025-05-06T14:41:56.730+0000] {taskinstance.py:2191} INFO - Executing <Task(PythonOperator): extract.extract_and_load_to_staging> on 2025-01-23 00:00:00+00:00
[2025-05-06T14:41:56.738+0000] {standard_task_runner.py:60} INFO - Started process 1355 to run task
[2025-05-06T14:41:56.741+0000] {standard_task_runner.py:87} INFO - Running: ['***', 'tasks', 'run', 'e_commerce_dw_etl', 'extract.extract_and_load_to_staging', 'scheduled__2025-01-23T00:00:00+00:00', '--job-id', '92', '--raw', '--subdir', 'DAGS_FOLDER/e_commerce_dw_dag.py', '--cfg-path', '/tmp/tmp696v176e']
[2025-05-06T14:41:56.743+0000] {standard_task_runner.py:88} INFO - Job 92: Subtask extract.extract_and_load_to_staging
[2025-05-06T14:41:56.948+0000] {logging_mixin.py:188} WARNING - /home/***/.local/lib/python3.8/site-packages/***/settings.py:194 DeprecationWarning: The sql_alchemy_conn option in [core] has been moved to the sql_alchemy_conn option in [database] - the old setting has been used, but please update your config.
[2025-05-06T14:41:56.991+0000] {task_command.py:423} INFO - Running <TaskInstance: e_commerce_dw_etl.extract.extract_and_load_to_staging scheduled__2025-01-23T00:00:00+00:00 [running]> on host 4e8b8c3535ca
[2025-05-06T14:41:57.107+0000] {taskinstance.py:2480} INFO - Exporting env vars: AIRFLOW_CTX_DAG_OWNER='***' AIRFLOW_CTX_DAG_ID='e_commerce_dw_etl' AIRFLOW_CTX_TASK_ID='extract.extract_and_load_to_staging' AIRFLOW_CTX_EXECUTION_DATE='2025-01-23T00:00:00+00:00' AIRFLOW_CTX_TRY_NUMBER='1' AIRFLOW_CTX_DAG_RUN_ID='scheduled__2025-01-23T00:00:00+00:00'
[2025-05-06T14:41:57.120+0000] {mysql_operator.py:13} ERROR - Can't connect to mysql database
[2025-05-06T14:41:57.141+0000] {taskinstance.py:2698} ERROR - Task failed with exception
Traceback (most recent call last):
  File "/home/airflow/.local/lib/python3.8/site-packages/airflow/models/taskinstance.py", line 433, in _execute_task
    result = execute_callable(context=context, **execute_callable_kwargs)
  File "/home/airflow/.local/lib/python3.8/site-packages/airflow/operators/python.py", line 199, in execute
    return_value = self.execute_callable()
  File "/home/airflow/.local/lib/python3.8/site-packages/airflow/operators/python.py", line 216, in execute_callable
    return self.python_callable(*self.op_args, **self.op_kwargs)
  File "/opt/airflow/dags/extract_data.py", line 30, in extract_and_load_to_staging
    df = source_operator.get_data_to_pd(f"SELECT * FROM {table}")
  File "/opt/airflow/plugins/mysql_operator.py", line 15, in get_data_to_pd
    return self.mysqlhook.get_pandas_df(query)
  File "/home/airflow/.local/lib/python3.8/site-packages/airflow/providers/common/sql/hooks/sql.py", line 220, in get_pandas_df
    with closing(self.get_conn()) as conn:
  File "/home/airflow/.local/lib/python3.8/site-packages/airflow/providers/mysql/hooks/mysql.py", line 187, in get_conn
    conn = self.connection or self.get_connection(getattr(self, self.conn_name_attr))
  File "/home/airflow/.local/lib/python3.8/site-packages/airflow/hooks/base.py", line 82, in get_connection
    conn = Connection.get_connection_from_secrets(conn_id)
  File "/home/airflow/.local/lib/python3.8/site-packages/airflow/models/connection.py", line 479, in get_connection_from_secrets
    raise AirflowNotFoundException(f"The conn_id `{conn_id}` isn't defined")
airflow.exceptions.AirflowNotFoundException: The conn_id `mysql` isn't defined
[2025-05-06T14:41:57.153+0000] {taskinstance.py:1138} INFO - Marking task as FAILED. dag_id=e_commerce_dw_etl, task_id=extract.extract_and_load_to_staging, execution_date=20250123T000000, start_date=20250506T144156, end_date=20250506T144157
[2025-05-06T14:41:57.170+0000] {standard_task_runner.py:107} ERROR - Failed to execute job 92 for task extract.extract_and_load_to_staging (The conn_id `mysql` isn't defined; 1355)
[2025-05-06T14:41:57.198+0000] {local_task_job_runner.py:234} INFO - Task exited with return code 1
[2025-05-06T14:41:57.441+0000] {taskinstance.py:3280} INFO - 0 downstream tasks scheduled from follow-on schedule check
[2025-05-08T10:43:49.952+0000] {taskinstance.py:1956} INFO - Dependencies all met for dep_context=non-requeueable deps ti=<TaskInstance: e_commerce_dw_etl.extract.extract_and_load_to_staging scheduled__2025-01-23T00:00:00+00:00 [queued]>
[2025-05-08T10:43:49.969+0000] {taskinstance.py:1956} INFO - Dependencies all met for dep_context=requeueable deps ti=<TaskInstance: e_commerce_dw_etl.extract.extract_and_load_to_staging scheduled__2025-01-23T00:00:00+00:00 [queued]>
[2025-05-08T10:43:49.970+0000] {taskinstance.py:2170} INFO - Starting attempt 1 of 1
[2025-05-08T10:43:50.040+0000] {taskinstance.py:2191} INFO - Executing <Task(PythonOperator): extract.extract_and_load_to_staging> on 2025-01-23 00:00:00+00:00
[2025-05-08T10:43:50.051+0000] {standard_task_runner.py:60} INFO - Started process 553 to run task
[2025-05-08T10:43:50.056+0000] {standard_task_runner.py:87} INFO - Running: ['***', 'tasks', 'run', 'e_commerce_dw_etl', 'extract.extract_and_load_to_staging', 'scheduled__2025-01-23T00:00:00+00:00', '--job-id', '778', '--raw', '--subdir', 'DAGS_FOLDER/e_commerce_dw_dag.py', '--cfg-path', '/tmp/tmphvzq8s93']
[2025-05-08T10:43:50.061+0000] {standard_task_runner.py:88} INFO - Job 778: Subtask extract.extract_and_load_to_staging
[2025-05-08T10:43:50.306+0000] {logging_mixin.py:188} WARNING - /home/***/.local/lib/python3.8/site-packages/***/settings.py:194 DeprecationWarning: The sql_alchemy_conn option in [core] has been moved to the sql_alchemy_conn option in [database] - the old setting has been used, but please update your config.
[2025-05-08T10:43:50.355+0000] {task_command.py:423} INFO - Running <TaskInstance: e_commerce_dw_etl.extract.extract_and_load_to_staging scheduled__2025-01-23T00:00:00+00:00 [running]> on host 274dc1d73528
[2025-05-08T10:43:50.472+0000] {taskinstance.py:2480} INFO - Exporting env vars: AIRFLOW_CTX_DAG_OWNER='***' AIRFLOW_CTX_DAG_ID='e_commerce_dw_etl' AIRFLOW_CTX_TASK_ID='extract.extract_and_load_to_staging' AIRFLOW_CTX_EXECUTION_DATE='2025-01-23T00:00:00+00:00' AIRFLOW_CTX_TRY_NUMBER='1' AIRFLOW_CTX_DAG_RUN_ID='scheduled__2025-01-23T00:00:00+00:00'
[2025-05-08T10:43:50.486+0000] {mysql_operator.py:13} ERROR - Can't connect to mysql database
[2025-05-08T10:43:50.515+0000] {taskinstance.py:2698} ERROR - Task failed with exception
Traceback (most recent call last):
  File "/home/airflow/.local/lib/python3.8/site-packages/airflow/models/taskinstance.py", line 433, in _execute_task
    result = execute_callable(context=context, **execute_callable_kwargs)
  File "/home/airflow/.local/lib/python3.8/site-packages/airflow/operators/python.py", line 199, in execute
    return_value = self.execute_callable()
  File "/home/airflow/.local/lib/python3.8/site-packages/airflow/operators/python.py", line 216, in execute_callable
    return self.python_callable(*self.op_args, **self.op_kwargs)
  File "/opt/airflow/dags/extract_data.py", line 30, in extract_and_load_to_staging
    df = source_operator.get_data_to_pd(f"SELECT * FROM {table}")
  File "/opt/airflow/plugins/mysql_operator.py", line 15, in get_data_to_pd
    return self.mysqlhook.get_pandas_df(query)
  File "/home/airflow/.local/lib/python3.8/site-packages/airflow/providers/common/sql/hooks/sql.py", line 220, in get_pandas_df
    with closing(self.get_conn()) as conn:
  File "/home/airflow/.local/lib/python3.8/site-packages/airflow/providers/mysql/hooks/mysql.py", line 187, in get_conn
    conn = self.connection or self.get_connection(getattr(self, self.conn_name_attr))
  File "/home/airflow/.local/lib/python3.8/site-packages/airflow/hooks/base.py", line 82, in get_connection
    conn = Connection.get_connection_from_secrets(conn_id)
  File "/home/airflow/.local/lib/python3.8/site-packages/airflow/models/connection.py", line 479, in get_connection_from_secrets
    raise AirflowNotFoundException(f"The conn_id `{conn_id}` isn't defined")
airflow.exceptions.AirflowNotFoundException: The conn_id `mysql` isn't defined
[2025-05-08T10:43:50.531+0000] {taskinstance.py:1138} INFO - Marking task as FAILED. dag_id=e_commerce_dw_etl, task_id=extract.extract_and_load_to_staging, execution_date=20250123T000000, start_date=20250508T104349, end_date=20250508T104350
[2025-05-08T10:43:50.651+0000] {standard_task_runner.py:107} ERROR - Failed to execute job 778 for task extract.extract_and_load_to_staging (The conn_id `mysql` isn't defined; 553)
[2025-05-08T10:43:50.671+0000] {local_task_job_runner.py:234} INFO - Task exited with return code 1
[2025-05-08T10:43:50.919+0000] {taskinstance.py:3280} INFO - 0 downstream tasks scheduled from follow-on schedule check
[2025-05-08T11:06:20.344+0000] {taskinstance.py:1956} INFO - Dependencies all met for dep_context=non-requeueable deps ti=<TaskInstance: e_commerce_dw_etl.extract.extract_and_load_to_staging scheduled__2025-01-23T00:00:00+00:00 [queued]>
[2025-05-08T11:06:20.364+0000] {taskinstance.py:1956} INFO - Dependencies all met for dep_context=requeueable deps ti=<TaskInstance: e_commerce_dw_etl.extract.extract_and_load_to_staging scheduled__2025-01-23T00:00:00+00:00 [queued]>
[2025-05-08T11:06:20.367+0000] {taskinstance.py:2170} INFO - Starting attempt 1 of 1
[2025-05-08T11:06:20.405+0000] {taskinstance.py:2191} INFO - Executing <Task(PythonOperator): extract.extract_and_load_to_staging> on 2025-01-23 00:00:00+00:00
[2025-05-08T11:06:20.415+0000] {standard_task_runner.py:60} INFO - Started process 497 to run task
[2025-05-08T11:06:20.424+0000] {standard_task_runner.py:87} INFO - Running: ['***', 'tasks', 'run', 'e_commerce_dw_etl', 'extract.extract_and_load_to_staging', 'scheduled__2025-01-23T00:00:00+00:00', '--job-id', '976', '--raw', '--subdir', 'DAGS_FOLDER/e_commerce_dw_dag.py', '--cfg-path', '/tmp/tmp3nq5tt7t']
[2025-05-08T11:06:20.427+0000] {standard_task_runner.py:88} INFO - Job 976: Subtask extract.extract_and_load_to_staging
[2025-05-08T11:06:20.810+0000] {logging_mixin.py:188} WARNING - /home/***/.local/lib/python3.8/site-packages/***/settings.py:194 DeprecationWarning: The sql_alchemy_conn option in [core] has been moved to the sql_alchemy_conn option in [database] - the old setting has been used, but please update your config.
[2025-05-08T11:06:20.873+0000] {task_command.py:423} INFO - Running <TaskInstance: e_commerce_dw_etl.extract.extract_and_load_to_staging scheduled__2025-01-23T00:00:00+00:00 [running]> on host 14e98ede325e
[2025-05-08T11:06:21.081+0000] {taskinstance.py:2480} INFO - Exporting env vars: AIRFLOW_CTX_DAG_OWNER='***' AIRFLOW_CTX_DAG_ID='e_commerce_dw_etl' AIRFLOW_CTX_TASK_ID='extract.extract_and_load_to_staging' AIRFLOW_CTX_EXECUTION_DATE='2025-01-23T00:00:00+00:00' AIRFLOW_CTX_TRY_NUMBER='1' AIRFLOW_CTX_DAG_RUN_ID='scheduled__2025-01-23T00:00:00+00:00'
[2025-05-08T11:06:21.095+0000] {mysql_operator.py:13} ERROR - Can't connect to mysql database
[2025-05-08T11:06:21.119+0000] {taskinstance.py:2698} ERROR - Task failed with exception
Traceback (most recent call last):
  File "/home/airflow/.local/lib/python3.8/site-packages/airflow/models/taskinstance.py", line 433, in _execute_task
    result = execute_callable(context=context, **execute_callable_kwargs)
  File "/home/airflow/.local/lib/python3.8/site-packages/airflow/operators/python.py", line 199, in execute
    return_value = self.execute_callable()
  File "/home/airflow/.local/lib/python3.8/site-packages/airflow/operators/python.py", line 216, in execute_callable
    return self.python_callable(*self.op_args, **self.op_kwargs)
  File "/opt/airflow/dags/extract_data.py", line 30, in extract_and_load_to_staging
    df = source_operator.get_data_to_pd(f"SELECT * FROM {table}")
  File "/opt/airflow/plugins/mysql_operator.py", line 15, in get_data_to_pd
    return self.mysqlhook.get_pandas_df(query)
  File "/home/airflow/.local/lib/python3.8/site-packages/airflow/providers/common/sql/hooks/sql.py", line 220, in get_pandas_df
    with closing(self.get_conn()) as conn:
  File "/home/airflow/.local/lib/python3.8/site-packages/airflow/providers/mysql/hooks/mysql.py", line 187, in get_conn
    conn = self.connection or self.get_connection(getattr(self, self.conn_name_attr))
  File "/home/airflow/.local/lib/python3.8/site-packages/airflow/hooks/base.py", line 82, in get_connection
    conn = Connection.get_connection_from_secrets(conn_id)
  File "/home/airflow/.local/lib/python3.8/site-packages/airflow/models/connection.py", line 479, in get_connection_from_secrets
    raise AirflowNotFoundException(f"The conn_id `{conn_id}` isn't defined")
airflow.exceptions.AirflowNotFoundException: The conn_id `mysql` isn't defined
[2025-05-08T11:06:21.142+0000] {taskinstance.py:1138} INFO - Marking task as FAILED. dag_id=e_commerce_dw_etl, task_id=extract.extract_and_load_to_staging, execution_date=20250123T000000, start_date=20250508T110620, end_date=20250508T110621
[2025-05-08T11:06:21.161+0000] {standard_task_runner.py:107} ERROR - Failed to execute job 976 for task extract.extract_and_load_to_staging (The conn_id `mysql` isn't defined; 497)
[2025-05-08T11:06:21.217+0000] {local_task_job_runner.py:234} INFO - Task exited with return code 1
[2025-05-08T11:06:21.535+0000] {taskinstance.py:3280} INFO - 0 downstream tasks scheduled from follow-on schedule check
[2025-05-08T11:09:22.085+0000] {taskinstance.py:1956} INFO - Dependencies all met for dep_context=non-requeueable deps ti=<TaskInstance: e_commerce_dw_etl.extract.extract_and_load_to_staging scheduled__2025-01-23T00:00:00+00:00 [queued]>
[2025-05-08T11:09:22.099+0000] {taskinstance.py:1956} INFO - Dependencies all met for dep_context=requeueable deps ti=<TaskInstance: e_commerce_dw_etl.extract.extract_and_load_to_staging scheduled__2025-01-23T00:00:00+00:00 [queued]>
[2025-05-08T11:09:22.100+0000] {taskinstance.py:2170} INFO - Starting attempt 1 of 1
[2025-05-08T11:09:22.146+0000] {taskinstance.py:2191} INFO - Executing <Task(PythonOperator): extract.extract_and_load_to_staging> on 2025-01-23 00:00:00+00:00
[2025-05-08T11:09:22.155+0000] {standard_task_runner.py:60} INFO - Started process 1006 to run task
[2025-05-08T11:09:22.160+0000] {standard_task_runner.py:87} INFO - Running: ['***', 'tasks', 'run', 'e_commerce_dw_etl', 'extract.extract_and_load_to_staging', 'scheduled__2025-01-23T00:00:00+00:00', '--job-id', '1171', '--raw', '--subdir', 'DAGS_FOLDER/e_commerce_dw_dag.py', '--cfg-path', '/tmp/tmp01ie6p5g']
[2025-05-08T11:09:22.163+0000] {standard_task_runner.py:88} INFO - Job 1171: Subtask extract.extract_and_load_to_staging
[2025-05-08T11:09:22.351+0000] {logging_mixin.py:188} WARNING - /home/***/.local/lib/python3.8/site-packages/***/settings.py:194 DeprecationWarning: The sql_alchemy_conn option in [core] has been moved to the sql_alchemy_conn option in [database] - the old setting has been used, but please update your config.
[2025-05-08T11:09:22.386+0000] {task_command.py:423} INFO - Running <TaskInstance: e_commerce_dw_etl.extract.extract_and_load_to_staging scheduled__2025-01-23T00:00:00+00:00 [running]> on host 14e98ede325e
[2025-05-08T11:09:22.469+0000] {taskinstance.py:2480} INFO - Exporting env vars: AIRFLOW_CTX_DAG_OWNER='***' AIRFLOW_CTX_DAG_ID='e_commerce_dw_etl' AIRFLOW_CTX_TASK_ID='extract.extract_and_load_to_staging' AIRFLOW_CTX_EXECUTION_DATE='2025-01-23T00:00:00+00:00' AIRFLOW_CTX_TRY_NUMBER='1' AIRFLOW_CTX_DAG_RUN_ID='scheduled__2025-01-23T00:00:00+00:00'
[2025-05-08T11:09:22.477+0000] {crypto.py:82} WARNING - empty cryptography key - values will not be stored encrypted.
[2025-05-08T11:09:22.479+0000] {connection.py:473} ERROR - Unable to retrieve connection from secrets backend (MetastoreBackend). Checking subsequent secrets backend.
Traceback (most recent call last):
  File "/home/airflow/.local/lib/python3.8/site-packages/airflow/models/connection.py", line 468, in get_connection_from_secrets
    conn = secrets_backend.get_connection(conn_id=conn_id)
  File "/home/airflow/.local/lib/python3.8/site-packages/airflow/utils/session.py", line 79, in wrapper
    return func(*args, session=session, **kwargs)
  File "/home/airflow/.local/lib/python3.8/site-packages/airflow/secrets/metastore.py", line 42, in get_connection
    return MetastoreBackend._fetch_connection(conn_id, session=session)
  File "/home/airflow/.local/lib/python3.8/site-packages/airflow/api_internal/internal_api_call.py", line 114, in wrapper
    return func(*args, **kwargs)
  File "/home/airflow/.local/lib/python3.8/site-packages/airflow/utils/session.py", line 76, in wrapper
    return func(*args, **kwargs)
  File "/home/airflow/.local/lib/python3.8/site-packages/airflow/secrets/metastore.py", line 73, in _fetch_connection
    conn = session.scalar(select(Connection).where(Connection.conn_id == conn_id).limit(1))
  File "/home/airflow/.local/lib/python3.8/site-packages/sqlalchemy/orm/session.py", line 1747, in scalar
    return self.execute(
  File "/home/airflow/.local/lib/python3.8/site-packages/sqlalchemy/engine/result.py", line 1276, in scalar
    return self._only_one_row(
  File "/home/airflow/.local/lib/python3.8/site-packages/sqlalchemy/engine/result.py", line 559, in _only_one_row
    row = onerow(hard_close=True)
  File "/home/airflow/.local/lib/python3.8/site-packages/sqlalchemy/engine/result.py", line 1801, in _fetchone_impl
    row = next(self.iterator, _NO_ROW)
  File "/home/airflow/.local/lib/python3.8/site-packages/sqlalchemy/orm/loading.py", line 151, in chunks
    rows = [proc(row) for row in fetch]
  File "/home/airflow/.local/lib/python3.8/site-packages/sqlalchemy/orm/loading.py", line 151, in <listcomp>
    rows = [proc(row) for row in fetch]
  File "/home/airflow/.local/lib/python3.8/site-packages/sqlalchemy/orm/loading.py", line 984, in _instance
    state.manager.dispatch.load(state, context)
  File "/home/airflow/.local/lib/python3.8/site-packages/sqlalchemy/event/attr.py", line 346, in __call__
    fn(*args, **kw)
  File "/home/airflow/.local/lib/python3.8/site-packages/sqlalchemy/orm/mapper.py", line 3702, in _event_on_load
    instrumenting_mapper._reconstructor(state.obj())
  File "/home/airflow/.local/lib/python3.8/site-packages/airflow/models/connection.py", line 174, in on_db_load
    if self.password:
  File "/home/airflow/.local/lib/python3.8/site-packages/sqlalchemy/orm/attributes.py", line 606, in __get__
    retval = self.descriptor.__get__(instance, owner)
  File "/home/airflow/.local/lib/python3.8/site-packages/airflow/models/connection.py", line 296, in get_password
    raise AirflowException(
airflow.exceptions.AirflowException: Can't decrypt encrypted password for login=***  FERNET_KEY configuration is missing
[2025-05-08T11:09:22.483+0000] {mysql_operator.py:13} ERROR - Can't connect to mysql database
[2025-05-08T11:09:22.490+0000] {connection.py:473} ERROR - Unable to retrieve connection from secrets backend (MetastoreBackend). Checking subsequent secrets backend.
Traceback (most recent call last):
  File "/home/airflow/.local/lib/python3.8/site-packages/airflow/models/connection.py", line 468, in get_connection_from_secrets
    conn = secrets_backend.get_connection(conn_id=conn_id)
  File "/home/airflow/.local/lib/python3.8/site-packages/airflow/utils/session.py", line 79, in wrapper
    return func(*args, session=session, **kwargs)
  File "/home/airflow/.local/lib/python3.8/site-packages/airflow/secrets/metastore.py", line 42, in get_connection
    return MetastoreBackend._fetch_connection(conn_id, session=session)
  File "/home/airflow/.local/lib/python3.8/site-packages/airflow/api_internal/internal_api_call.py", line 114, in wrapper
    return func(*args, **kwargs)
  File "/home/airflow/.local/lib/python3.8/site-packages/airflow/utils/session.py", line 76, in wrapper
    return func(*args, **kwargs)
  File "/home/airflow/.local/lib/python3.8/site-packages/airflow/secrets/metastore.py", line 73, in _fetch_connection
    conn = session.scalar(select(Connection).where(Connection.conn_id == conn_id).limit(1))
  File "/home/airflow/.local/lib/python3.8/site-packages/sqlalchemy/orm/session.py", line 1747, in scalar
    return self.execute(
  File "/home/airflow/.local/lib/python3.8/site-packages/sqlalchemy/engine/result.py", line 1276, in scalar
    return self._only_one_row(
  File "/home/airflow/.local/lib/python3.8/site-packages/sqlalchemy/engine/result.py", line 559, in _only_one_row
    row = onerow(hard_close=True)
  File "/home/airflow/.local/lib/python3.8/site-packages/sqlalchemy/engine/result.py", line 1801, in _fetchone_impl
    row = next(self.iterator, _NO_ROW)
  File "/home/airflow/.local/lib/python3.8/site-packages/sqlalchemy/orm/loading.py", line 151, in chunks
    rows = [proc(row) for row in fetch]
  File "/home/airflow/.local/lib/python3.8/site-packages/sqlalchemy/orm/loading.py", line 151, in <listcomp>
    rows = [proc(row) for row in fetch]
  File "/home/airflow/.local/lib/python3.8/site-packages/sqlalchemy/orm/loading.py", line 984, in _instance
    state.manager.dispatch.load(state, context)
  File "/home/airflow/.local/lib/python3.8/site-packages/sqlalchemy/event/attr.py", line 346, in __call__
    fn(*args, **kw)
  File "/home/airflow/.local/lib/python3.8/site-packages/sqlalchemy/orm/mapper.py", line 3702, in _event_on_load
    instrumenting_mapper._reconstructor(state.obj())
  File "/home/airflow/.local/lib/python3.8/site-packages/airflow/models/connection.py", line 174, in on_db_load
    if self.password:
  File "/home/airflow/.local/lib/python3.8/site-packages/sqlalchemy/orm/attributes.py", line 606, in __get__
    retval = self.descriptor.__get__(instance, owner)
  File "/home/airflow/.local/lib/python3.8/site-packages/airflow/models/connection.py", line 296, in get_password
    raise AirflowException(
airflow.exceptions.AirflowException: Can't decrypt encrypted password for login=***  FERNET_KEY configuration is missing
[2025-05-08T11:09:22.499+0000] {taskinstance.py:2698} ERROR - Task failed with exception
Traceback (most recent call last):
  File "/home/airflow/.local/lib/python3.8/site-packages/airflow/models/taskinstance.py", line 433, in _execute_task
    result = execute_callable(context=context, **execute_callable_kwargs)
  File "/home/airflow/.local/lib/python3.8/site-packages/airflow/operators/python.py", line 199, in execute
    return_value = self.execute_callable()
  File "/home/airflow/.local/lib/python3.8/site-packages/airflow/operators/python.py", line 216, in execute_callable
    return self.python_callable(*self.op_args, **self.op_kwargs)
  File "/opt/airflow/dags/extract_data.py", line 30, in extract_and_load_to_staging
    df = source_operator.get_data_to_pd(f"SELECT * FROM {table}")
  File "/opt/airflow/plugins/mysql_operator.py", line 15, in get_data_to_pd
    return self.mysqlhook.get_pandas_df(query)
  File "/home/airflow/.local/lib/python3.8/site-packages/airflow/providers/common/sql/hooks/sql.py", line 220, in get_pandas_df
    with closing(self.get_conn()) as conn:
  File "/home/airflow/.local/lib/python3.8/site-packages/airflow/providers/mysql/hooks/mysql.py", line 187, in get_conn
    conn = self.connection or self.get_connection(getattr(self, self.conn_name_attr))
  File "/home/airflow/.local/lib/python3.8/site-packages/airflow/hooks/base.py", line 82, in get_connection
    conn = Connection.get_connection_from_secrets(conn_id)
  File "/home/airflow/.local/lib/python3.8/site-packages/airflow/models/connection.py", line 479, in get_connection_from_secrets
    raise AirflowNotFoundException(f"The conn_id `{conn_id}` isn't defined")
airflow.exceptions.AirflowNotFoundException: The conn_id `mysql` isn't defined
[2025-05-08T11:09:22.510+0000] {taskinstance.py:1138} INFO - Marking task as FAILED. dag_id=e_commerce_dw_etl, task_id=extract.extract_and_load_to_staging, execution_date=20250123T000000, start_date=20250508T110922, end_date=20250508T110922
[2025-05-08T11:09:22.523+0000] {standard_task_runner.py:107} ERROR - Failed to execute job 1171 for task extract.extract_and_load_to_staging (The conn_id `mysql` isn't defined; 1006)
[2025-05-08T11:09:22.573+0000] {local_task_job_runner.py:234} INFO - Task exited with return code 1
[2025-05-08T11:09:22.705+0000] {taskinstance.py:3280} INFO - 0 downstream tasks scheduled from follow-on schedule check
[2025-05-08T11:15:15.435+0000] {taskinstance.py:1956} INFO - Dependencies all met for dep_context=non-requeueable deps ti=<TaskInstance: e_commerce_dw_etl.extract.extract_and_load_to_staging scheduled__2025-01-23T00:00:00+00:00 [queued]>
[2025-05-08T11:15:15.448+0000] {taskinstance.py:1956} INFO - Dependencies all met for dep_context=requeueable deps ti=<TaskInstance: e_commerce_dw_etl.extract.extract_and_load_to_staging scheduled__2025-01-23T00:00:00+00:00 [queued]>
[2025-05-08T11:15:15.449+0000] {taskinstance.py:2170} INFO - Starting attempt 1 of 1
[2025-05-08T11:15:15.470+0000] {taskinstance.py:2191} INFO - Executing <Task(PythonOperator): extract.extract_and_load_to_staging> on 2025-01-23 00:00:00+00:00
[2025-05-08T11:15:15.478+0000] {standard_task_runner.py:60} INFO - Started process 434 to run task
[2025-05-08T11:15:15.480+0000] {standard_task_runner.py:87} INFO - Running: ['***', 'tasks', 'run', 'e_commerce_dw_etl', 'extract.extract_and_load_to_staging', 'scheduled__2025-01-23T00:00:00+00:00', '--job-id', '1366', '--raw', '--subdir', 'DAGS_FOLDER/e_commerce_dw_dag.py', '--cfg-path', '/tmp/tmp3ara63kc']
[2025-05-08T11:15:15.482+0000] {standard_task_runner.py:88} INFO - Job 1366: Subtask extract.extract_and_load_to_staging
[2025-05-08T11:15:15.684+0000] {logging_mixin.py:188} WARNING - /home/***/.local/lib/python3.8/site-packages/***/settings.py:194 DeprecationWarning: The sql_alchemy_conn option in [core] has been moved to the sql_alchemy_conn option in [database] - the old setting has been used, but please update your config.
[2025-05-08T11:15:15.722+0000] {task_command.py:423} INFO - Running <TaskInstance: e_commerce_dw_etl.extract.extract_and_load_to_staging scheduled__2025-01-23T00:00:00+00:00 [running]> on host 3623a279d4d4
[2025-05-08T11:15:15.831+0000] {taskinstance.py:2480} INFO - Exporting env vars: AIRFLOW_CTX_DAG_OWNER='***' AIRFLOW_CTX_DAG_ID='e_commerce_dw_etl' AIRFLOW_CTX_TASK_ID='extract.extract_and_load_to_staging' AIRFLOW_CTX_EXECUTION_DATE='2025-01-23T00:00:00+00:00' AIRFLOW_CTX_TRY_NUMBER='1' AIRFLOW_CTX_DAG_RUN_ID='scheduled__2025-01-23T00:00:00+00:00'
[2025-05-08T11:15:15.843+0000] {mysql_operator.py:13} ERROR - Can't connect to mysql_default database
[2025-05-08T11:15:15.864+0000] {taskinstance.py:2698} ERROR - Task failed with exception
Traceback (most recent call last):
  File "/home/airflow/.local/lib/python3.8/site-packages/airflow/models/taskinstance.py", line 433, in _execute_task
    result = execute_callable(context=context, **execute_callable_kwargs)
  File "/home/airflow/.local/lib/python3.8/site-packages/airflow/operators/python.py", line 199, in execute
    return_value = self.execute_callable()
  File "/home/airflow/.local/lib/python3.8/site-packages/airflow/operators/python.py", line 216, in execute_callable
    return self.python_callable(*self.op_args, **self.op_kwargs)
  File "/opt/airflow/dags/extract_data.py", line 30, in extract_and_load_to_staging
    df = source_operator.get_data_to_pd(f"SELECT * FROM {table}")
  File "/opt/airflow/plugins/mysql_operator.py", line 15, in get_data_to_pd
    return self.mysqlhook.get_pandas_df(query)
  File "/home/airflow/.local/lib/python3.8/site-packages/airflow/providers/common/sql/hooks/sql.py", line 220, in get_pandas_df
    with closing(self.get_conn()) as conn:
  File "/home/airflow/.local/lib/python3.8/site-packages/airflow/providers/mysql/hooks/mysql.py", line 187, in get_conn
    conn = self.connection or self.get_connection(getattr(self, self.conn_name_attr))
  File "/home/airflow/.local/lib/python3.8/site-packages/airflow/hooks/base.py", line 82, in get_connection
    conn = Connection.get_connection_from_secrets(conn_id)
  File "/home/airflow/.local/lib/python3.8/site-packages/airflow/models/connection.py", line 479, in get_connection_from_secrets
    raise AirflowNotFoundException(f"The conn_id `{conn_id}` isn't defined")
airflow.exceptions.AirflowNotFoundException: The conn_id `mysql_default` isn't defined
[2025-05-08T11:15:15.877+0000] {taskinstance.py:1138} INFO - Marking task as FAILED. dag_id=e_commerce_dw_etl, task_id=extract.extract_and_load_to_staging, execution_date=20250123T000000, start_date=20250508T111515, end_date=20250508T111515
[2025-05-08T11:15:15.894+0000] {standard_task_runner.py:107} ERROR - Failed to execute job 1366 for task extract.extract_and_load_to_staging (The conn_id `mysql_default` isn't defined; 434)
[2025-05-08T11:15:15.936+0000] {local_task_job_runner.py:234} INFO - Task exited with return code 1
[2025-05-08T11:15:16.206+0000] {taskinstance.py:3280} INFO - 0 downstream tasks scheduled from follow-on schedule check
[2025-05-08T11:20:27.729+0000] {taskinstance.py:1956} INFO - Dependencies all met for dep_context=non-requeueable deps ti=<TaskInstance: e_commerce_dw_etl.extract.extract_and_load_to_staging scheduled__2025-01-23T00:00:00+00:00 [queued]>
[2025-05-08T11:20:27.749+0000] {taskinstance.py:1956} INFO - Dependencies all met for dep_context=requeueable deps ti=<TaskInstance: e_commerce_dw_etl.extract.extract_and_load_to_staging scheduled__2025-01-23T00:00:00+00:00 [queued]>
[2025-05-08T11:20:27.751+0000] {taskinstance.py:2170} INFO - Starting attempt 1 of 1
[2025-05-08T11:20:27.788+0000] {taskinstance.py:2191} INFO - Executing <Task(PythonOperator): extract.extract_and_load_to_staging> on 2025-01-23 00:00:00+00:00
[2025-05-08T11:20:27.797+0000] {standard_task_runner.py:60} INFO - Started process 1222 to run task
[2025-05-08T11:20:27.808+0000] {standard_task_runner.py:87} INFO - Running: ['***', 'tasks', 'run', 'e_commerce_dw_etl', 'extract.extract_and_load_to_staging', 'scheduled__2025-01-23T00:00:00+00:00', '--job-id', '1661', '--raw', '--subdir', 'DAGS_FOLDER/e_commerce_dw_dag.py', '--cfg-path', '/tmp/tmpgexzt5my']
[2025-05-08T11:20:27.812+0000] {standard_task_runner.py:88} INFO - Job 1661: Subtask extract.extract_and_load_to_staging
[2025-05-08T11:20:28.223+0000] {logging_mixin.py:188} WARNING - /home/***/.local/lib/python3.8/site-packages/***/settings.py:194 DeprecationWarning: The sql_alchemy_conn option in [core] has been moved to the sql_alchemy_conn option in [database] - the old setting has been used, but please update your config.
[2025-05-08T11:20:28.313+0000] {task_command.py:423} INFO - Running <TaskInstance: e_commerce_dw_etl.extract.extract_and_load_to_staging scheduled__2025-01-23T00:00:00+00:00 [running]> on host 3623a279d4d4
[2025-05-08T11:20:28.469+0000] {taskinstance.py:2480} INFO - Exporting env vars: AIRFLOW_CTX_DAG_OWNER='***' AIRFLOW_CTX_DAG_ID='e_commerce_dw_etl' AIRFLOW_CTX_TASK_ID='extract.extract_and_load_to_staging' AIRFLOW_CTX_EXECUTION_DATE='2025-01-23T00:00:00+00:00' AIRFLOW_CTX_TRY_NUMBER='1' AIRFLOW_CTX_DAG_RUN_ID='scheduled__2025-01-23T00:00:00+00:00'
[2025-05-08T11:20:28.512+0000] {crypto.py:82} WARNING - empty cryptography key - values will not be stored encrypted.
[2025-05-08T11:20:28.517+0000] {connection.py:473} ERROR - Unable to retrieve connection from secrets backend (MetastoreBackend). Checking subsequent secrets backend.
Traceback (most recent call last):
  File "/home/airflow/.local/lib/python3.8/site-packages/airflow/models/connection.py", line 468, in get_connection_from_secrets
    conn = secrets_backend.get_connection(conn_id=conn_id)
  File "/home/airflow/.local/lib/python3.8/site-packages/airflow/utils/session.py", line 79, in wrapper
    return func(*args, session=session, **kwargs)
  File "/home/airflow/.local/lib/python3.8/site-packages/airflow/secrets/metastore.py", line 42, in get_connection
    return MetastoreBackend._fetch_connection(conn_id, session=session)
  File "/home/airflow/.local/lib/python3.8/site-packages/airflow/api_internal/internal_api_call.py", line 114, in wrapper
    return func(*args, **kwargs)
  File "/home/airflow/.local/lib/python3.8/site-packages/airflow/utils/session.py", line 76, in wrapper
    return func(*args, **kwargs)
  File "/home/airflow/.local/lib/python3.8/site-packages/airflow/secrets/metastore.py", line 73, in _fetch_connection
    conn = session.scalar(select(Connection).where(Connection.conn_id == conn_id).limit(1))
  File "/home/airflow/.local/lib/python3.8/site-packages/sqlalchemy/orm/session.py", line 1747, in scalar
    return self.execute(
  File "/home/airflow/.local/lib/python3.8/site-packages/sqlalchemy/engine/result.py", line 1276, in scalar
    return self._only_one_row(
  File "/home/airflow/.local/lib/python3.8/site-packages/sqlalchemy/engine/result.py", line 559, in _only_one_row
    row = onerow(hard_close=True)
  File "/home/airflow/.local/lib/python3.8/site-packages/sqlalchemy/engine/result.py", line 1801, in _fetchone_impl
    row = next(self.iterator, _NO_ROW)
  File "/home/airflow/.local/lib/python3.8/site-packages/sqlalchemy/orm/loading.py", line 151, in chunks
    rows = [proc(row) for row in fetch]
  File "/home/airflow/.local/lib/python3.8/site-packages/sqlalchemy/orm/loading.py", line 151, in <listcomp>
    rows = [proc(row) for row in fetch]
  File "/home/airflow/.local/lib/python3.8/site-packages/sqlalchemy/orm/loading.py", line 984, in _instance
    state.manager.dispatch.load(state, context)
  File "/home/airflow/.local/lib/python3.8/site-packages/sqlalchemy/event/attr.py", line 346, in __call__
    fn(*args, **kw)
  File "/home/airflow/.local/lib/python3.8/site-packages/sqlalchemy/orm/mapper.py", line 3702, in _event_on_load
    instrumenting_mapper._reconstructor(state.obj())
  File "/home/airflow/.local/lib/python3.8/site-packages/airflow/models/connection.py", line 174, in on_db_load
    if self.password:
  File "/home/airflow/.local/lib/python3.8/site-packages/sqlalchemy/orm/attributes.py", line 606, in __get__
    retval = self.descriptor.__get__(instance, owner)
  File "/home/airflow/.local/lib/python3.8/site-packages/airflow/models/connection.py", line 296, in get_password
    raise AirflowException(
airflow.exceptions.AirflowException: Can't decrypt encrypted password for login=***  FERNET_KEY configuration is missing
[2025-05-08T11:20:28.526+0000] {mysql_operator.py:13} ERROR - Can't connect to mysql database
[2025-05-08T11:20:28.540+0000] {connection.py:473} ERROR - Unable to retrieve connection from secrets backend (MetastoreBackend). Checking subsequent secrets backend.
Traceback (most recent call last):
  File "/home/airflow/.local/lib/python3.8/site-packages/airflow/models/connection.py", line 468, in get_connection_from_secrets
    conn = secrets_backend.get_connection(conn_id=conn_id)
  File "/home/airflow/.local/lib/python3.8/site-packages/airflow/utils/session.py", line 79, in wrapper
    return func(*args, session=session, **kwargs)
  File "/home/airflow/.local/lib/python3.8/site-packages/airflow/secrets/metastore.py", line 42, in get_connection
    return MetastoreBackend._fetch_connection(conn_id, session=session)
  File "/home/airflow/.local/lib/python3.8/site-packages/airflow/api_internal/internal_api_call.py", line 114, in wrapper
    return func(*args, **kwargs)
  File "/home/airflow/.local/lib/python3.8/site-packages/airflow/utils/session.py", line 76, in wrapper
    return func(*args, **kwargs)
  File "/home/airflow/.local/lib/python3.8/site-packages/airflow/secrets/metastore.py", line 73, in _fetch_connection
    conn = session.scalar(select(Connection).where(Connection.conn_id == conn_id).limit(1))
  File "/home/airflow/.local/lib/python3.8/site-packages/sqlalchemy/orm/session.py", line 1747, in scalar
    return self.execute(
  File "/home/airflow/.local/lib/python3.8/site-packages/sqlalchemy/engine/result.py", line 1276, in scalar
    return self._only_one_row(
  File "/home/airflow/.local/lib/python3.8/site-packages/sqlalchemy/engine/result.py", line 559, in _only_one_row
    row = onerow(hard_close=True)
  File "/home/airflow/.local/lib/python3.8/site-packages/sqlalchemy/engine/result.py", line 1801, in _fetchone_impl
    row = next(self.iterator, _NO_ROW)
  File "/home/airflow/.local/lib/python3.8/site-packages/sqlalchemy/orm/loading.py", line 151, in chunks
    rows = [proc(row) for row in fetch]
  File "/home/airflow/.local/lib/python3.8/site-packages/sqlalchemy/orm/loading.py", line 151, in <listcomp>
    rows = [proc(row) for row in fetch]
  File "/home/airflow/.local/lib/python3.8/site-packages/sqlalchemy/orm/loading.py", line 984, in _instance
    state.manager.dispatch.load(state, context)
  File "/home/airflow/.local/lib/python3.8/site-packages/sqlalchemy/event/attr.py", line 346, in __call__
    fn(*args, **kw)
  File "/home/airflow/.local/lib/python3.8/site-packages/sqlalchemy/orm/mapper.py", line 3702, in _event_on_load
    instrumenting_mapper._reconstructor(state.obj())
  File "/home/airflow/.local/lib/python3.8/site-packages/airflow/models/connection.py", line 174, in on_db_load
    if self.password:
  File "/home/airflow/.local/lib/python3.8/site-packages/sqlalchemy/orm/attributes.py", line 606, in __get__
    retval = self.descriptor.__get__(instance, owner)
  File "/home/airflow/.local/lib/python3.8/site-packages/airflow/models/connection.py", line 296, in get_password
    raise AirflowException(
airflow.exceptions.AirflowException: Can't decrypt encrypted password for login=***  FERNET_KEY configuration is missing
[2025-05-08T11:20:28.561+0000] {taskinstance.py:2698} ERROR - Task failed with exception
Traceback (most recent call last):
  File "/home/airflow/.local/lib/python3.8/site-packages/airflow/models/taskinstance.py", line 433, in _execute_task
    result = execute_callable(context=context, **execute_callable_kwargs)
  File "/home/airflow/.local/lib/python3.8/site-packages/airflow/operators/python.py", line 199, in execute
    return_value = self.execute_callable()
  File "/home/airflow/.local/lib/python3.8/site-packages/airflow/operators/python.py", line 216, in execute_callable
    return self.python_callable(*self.op_args, **self.op_kwargs)
  File "/opt/airflow/dags/extract_data.py", line 30, in extract_and_load_to_staging
    df = source_operator.get_data_to_pd(f"SELECT * FROM {table}")
  File "/opt/airflow/plugins/mysql_operator.py", line 15, in get_data_to_pd
    return self.mysqlhook.get_pandas_df(query)
  File "/home/airflow/.local/lib/python3.8/site-packages/airflow/providers/common/sql/hooks/sql.py", line 220, in get_pandas_df
    with closing(self.get_conn()) as conn:
  File "/home/airflow/.local/lib/python3.8/site-packages/airflow/providers/mysql/hooks/mysql.py", line 187, in get_conn
    conn = self.connection or self.get_connection(getattr(self, self.conn_name_attr))
  File "/home/airflow/.local/lib/python3.8/site-packages/airflow/hooks/base.py", line 82, in get_connection
    conn = Connection.get_connection_from_secrets(conn_id)
  File "/home/airflow/.local/lib/python3.8/site-packages/airflow/models/connection.py", line 479, in get_connection_from_secrets
    raise AirflowNotFoundException(f"The conn_id `{conn_id}` isn't defined")
airflow.exceptions.AirflowNotFoundException: The conn_id `mysql` isn't defined
[2025-05-08T11:20:28.618+0000] {taskinstance.py:1138} INFO - Marking task as FAILED. dag_id=e_commerce_dw_etl, task_id=extract.extract_and_load_to_staging, execution_date=20250123T000000, start_date=20250508T112027, end_date=20250508T112028
[2025-05-08T11:20:28.851+0000] {standard_task_runner.py:107} ERROR - Failed to execute job 1661 for task extract.extract_and_load_to_staging (The conn_id `mysql` isn't defined; 1222)
[2025-05-08T11:20:28.901+0000] {local_task_job_runner.py:234} INFO - Task exited with return code 1
[2025-05-08T11:20:29.160+0000] {taskinstance.py:3280} INFO - 0 downstream tasks scheduled from follow-on schedule check
