[2025-05-06T14:41:37.407+0000] {taskinstance.py:1956} INFO - Dependencies all met for dep_context=non-requeueable deps ti=<TaskInstance: e_commerce_dw_etl.extract.extract_and_load_to_staging scheduled__2024-12-17T00:00:00+00:00 [queued]>
[2025-05-06T14:41:37.421+0000] {taskinstance.py:1956} INFO - Dependencies all met for dep_context=requeueable deps ti=<TaskInstance: e_commerce_dw_etl.extract.extract_and_load_to_staging scheduled__2024-12-17T00:00:00+00:00 [queued]>
[2025-05-06T14:41:37.422+0000] {taskinstance.py:2170} INFO - Starting attempt 1 of 1
[2025-05-06T14:41:37.563+0000] {taskinstance.py:2191} INFO - Executing <Task(PythonOperator): extract.extract_and_load_to_staging> on 2024-12-17 00:00:00+00:00
[2025-05-06T14:41:37.570+0000] {standard_task_runner.py:60} INFO - Started process 1280 to run task
[2025-05-06T14:41:37.574+0000] {standard_task_runner.py:87} INFO - Running: ['***', 'tasks', 'run', 'e_commerce_dw_etl', 'extract.extract_and_load_to_staging', 'scheduled__2024-12-17T00:00:00+00:00', '--job-id', '55', '--raw', '--subdir', 'DAGS_FOLDER/e_commerce_dw_dag.py', '--cfg-path', '/tmp/tmpao9rqpy6']
[2025-05-06T14:41:37.577+0000] {standard_task_runner.py:88} INFO - Job 55: Subtask extract.extract_and_load_to_staging
[2025-05-06T14:41:37.755+0000] {logging_mixin.py:188} WARNING - /home/***/.local/lib/python3.8/site-packages/***/settings.py:194 DeprecationWarning: The sql_alchemy_conn option in [core] has been moved to the sql_alchemy_conn option in [database] - the old setting has been used, but please update your config.
[2025-05-06T14:41:37.794+0000] {task_command.py:423} INFO - Running <TaskInstance: e_commerce_dw_etl.extract.extract_and_load_to_staging scheduled__2024-12-17T00:00:00+00:00 [running]> on host 4e8b8c3535ca
[2025-05-06T14:41:37.861+0000] {taskinstance.py:2480} INFO - Exporting env vars: AIRFLOW_CTX_DAG_OWNER='***' AIRFLOW_CTX_DAG_ID='e_commerce_dw_etl' AIRFLOW_CTX_TASK_ID='extract.extract_and_load_to_staging' AIRFLOW_CTX_EXECUTION_DATE='2024-12-17T00:00:00+00:00' AIRFLOW_CTX_TRY_NUMBER='1' AIRFLOW_CTX_DAG_RUN_ID='scheduled__2024-12-17T00:00:00+00:00'
[2025-05-06T14:41:37.869+0000] {mysql_operator.py:13} ERROR - Can't connect to mysql database
[2025-05-06T14:41:37.883+0000] {taskinstance.py:2698} ERROR - Task failed with exception
Traceback (most recent call last):
  File "/home/airflow/.local/lib/python3.8/site-packages/airflow/models/taskinstance.py", line 433, in _execute_task
    result = execute_callable(context=context, **execute_callable_kwargs)
  File "/home/airflow/.local/lib/python3.8/site-packages/airflow/operators/python.py", line 199, in execute
    return_value = self.execute_callable()
  File "/home/airflow/.local/lib/python3.8/site-packages/airflow/operators/python.py", line 216, in execute_callable
    return self.python_callable(*self.op_args, **self.op_kwargs)
  File "/opt/airflow/dags/extract_data.py", line 30, in extract_and_load_to_staging
    df = source_operator.get_data_to_pd(f"SELECT * FROM {table}")
  File "/opt/airflow/plugins/mysql_operator.py", line 15, in get_data_to_pd
    return self.mysqlhook.get_pandas_df(query)
  File "/home/airflow/.local/lib/python3.8/site-packages/airflow/providers/common/sql/hooks/sql.py", line 220, in get_pandas_df
    with closing(self.get_conn()) as conn:
  File "/home/airflow/.local/lib/python3.8/site-packages/airflow/providers/mysql/hooks/mysql.py", line 187, in get_conn
    conn = self.connection or self.get_connection(getattr(self, self.conn_name_attr))
  File "/home/airflow/.local/lib/python3.8/site-packages/airflow/hooks/base.py", line 82, in get_connection
    conn = Connection.get_connection_from_secrets(conn_id)
  File "/home/airflow/.local/lib/python3.8/site-packages/airflow/models/connection.py", line 479, in get_connection_from_secrets
    raise AirflowNotFoundException(f"The conn_id `{conn_id}` isn't defined")
airflow.exceptions.AirflowNotFoundException: The conn_id `mysql` isn't defined
[2025-05-06T14:41:37.896+0000] {taskinstance.py:1138} INFO - Marking task as FAILED. dag_id=e_commerce_dw_etl, task_id=extract.extract_and_load_to_staging, execution_date=20241217T000000, start_date=20250506T144137, end_date=20250506T144137
[2025-05-06T14:41:37.906+0000] {standard_task_runner.py:107} ERROR - Failed to execute job 55 for task extract.extract_and_load_to_staging (The conn_id `mysql` isn't defined; 1280)
[2025-05-06T14:41:37.948+0000] {local_task_job_runner.py:234} INFO - Task exited with return code 1
[2025-05-06T14:41:38.080+0000] {taskinstance.py:3280} INFO - 0 downstream tasks scheduled from follow-on schedule check
[2025-05-08T10:43:27.185+0000] {taskinstance.py:1956} INFO - Dependencies all met for dep_context=non-requeueable deps ti=<TaskInstance: e_commerce_dw_etl.extract.extract_and_load_to_staging scheduled__2024-12-17T00:00:00+00:00 [queued]>
[2025-05-08T10:43:27.199+0000] {taskinstance.py:1956} INFO - Dependencies all met for dep_context=requeueable deps ti=<TaskInstance: e_commerce_dw_etl.extract.extract_and_load_to_staging scheduled__2024-12-17T00:00:00+00:00 [queued]>
[2025-05-08T10:43:27.200+0000] {taskinstance.py:2170} INFO - Starting attempt 1 of 1
[2025-05-08T10:43:27.222+0000] {taskinstance.py:2191} INFO - Executing <Task(PythonOperator): extract.extract_and_load_to_staging> on 2024-12-17 00:00:00+00:00
[2025-05-08T10:43:27.228+0000] {standard_task_runner.py:60} INFO - Started process 457 to run task
[2025-05-08T10:43:27.233+0000] {standard_task_runner.py:87} INFO - Running: ['***', 'tasks', 'run', 'e_commerce_dw_etl', 'extract.extract_and_load_to_staging', 'scheduled__2024-12-17T00:00:00+00:00', '--job-id', '741', '--raw', '--subdir', 'DAGS_FOLDER/e_commerce_dw_dag.py', '--cfg-path', '/tmp/tmpjf2yre71']
[2025-05-08T10:43:27.236+0000] {standard_task_runner.py:88} INFO - Job 741: Subtask extract.extract_and_load_to_staging
[2025-05-08T10:43:27.403+0000] {logging_mixin.py:188} WARNING - /home/***/.local/lib/python3.8/site-packages/***/settings.py:194 DeprecationWarning: The sql_alchemy_conn option in [core] has been moved to the sql_alchemy_conn option in [database] - the old setting has been used, but please update your config.
[2025-05-08T10:43:27.432+0000] {task_command.py:423} INFO - Running <TaskInstance: e_commerce_dw_etl.extract.extract_and_load_to_staging scheduled__2024-12-17T00:00:00+00:00 [running]> on host 274dc1d73528
[2025-05-08T10:43:27.505+0000] {taskinstance.py:2480} INFO - Exporting env vars: AIRFLOW_CTX_DAG_OWNER='***' AIRFLOW_CTX_DAG_ID='e_commerce_dw_etl' AIRFLOW_CTX_TASK_ID='extract.extract_and_load_to_staging' AIRFLOW_CTX_EXECUTION_DATE='2024-12-17T00:00:00+00:00' AIRFLOW_CTX_TRY_NUMBER='1' AIRFLOW_CTX_DAG_RUN_ID='scheduled__2024-12-17T00:00:00+00:00'
[2025-05-08T10:43:27.512+0000] {mysql_operator.py:13} ERROR - Can't connect to mysql database
[2025-05-08T10:43:27.530+0000] {taskinstance.py:2698} ERROR - Task failed with exception
Traceback (most recent call last):
  File "/home/airflow/.local/lib/python3.8/site-packages/airflow/models/taskinstance.py", line 433, in _execute_task
    result = execute_callable(context=context, **execute_callable_kwargs)
  File "/home/airflow/.local/lib/python3.8/site-packages/airflow/operators/python.py", line 199, in execute
    return_value = self.execute_callable()
  File "/home/airflow/.local/lib/python3.8/site-packages/airflow/operators/python.py", line 216, in execute_callable
    return self.python_callable(*self.op_args, **self.op_kwargs)
  File "/opt/airflow/dags/extract_data.py", line 30, in extract_and_load_to_staging
    df = source_operator.get_data_to_pd(f"SELECT * FROM {table}")
  File "/opt/airflow/plugins/mysql_operator.py", line 15, in get_data_to_pd
    return self.mysqlhook.get_pandas_df(query)
  File "/home/airflow/.local/lib/python3.8/site-packages/airflow/providers/common/sql/hooks/sql.py", line 220, in get_pandas_df
    with closing(self.get_conn()) as conn:
  File "/home/airflow/.local/lib/python3.8/site-packages/airflow/providers/mysql/hooks/mysql.py", line 187, in get_conn
    conn = self.connection or self.get_connection(getattr(self, self.conn_name_attr))
  File "/home/airflow/.local/lib/python3.8/site-packages/airflow/hooks/base.py", line 82, in get_connection
    conn = Connection.get_connection_from_secrets(conn_id)
  File "/home/airflow/.local/lib/python3.8/site-packages/airflow/models/connection.py", line 479, in get_connection_from_secrets
    raise AirflowNotFoundException(f"The conn_id `{conn_id}` isn't defined")
airflow.exceptions.AirflowNotFoundException: The conn_id `mysql` isn't defined
[2025-05-08T10:43:27.542+0000] {taskinstance.py:1138} INFO - Marking task as FAILED. dag_id=e_commerce_dw_etl, task_id=extract.extract_and_load_to_staging, execution_date=20241217T000000, start_date=20250508T104327, end_date=20250508T104327
[2025-05-08T10:43:27.553+0000] {standard_task_runner.py:107} ERROR - Failed to execute job 741 for task extract.extract_and_load_to_staging (The conn_id `mysql` isn't defined; 457)
[2025-05-08T10:43:27.566+0000] {local_task_job_runner.py:234} INFO - Task exited with return code 1
[2025-05-08T10:43:27.688+0000] {taskinstance.py:3280} INFO - 0 downstream tasks scheduled from follow-on schedule check
[2025-05-08T11:06:01.597+0000] {taskinstance.py:1956} INFO - Dependencies all met for dep_context=non-requeueable deps ti=<TaskInstance: e_commerce_dw_etl.extract.extract_and_load_to_staging scheduled__2024-12-17T00:00:00+00:00 [queued]>
[2025-05-08T11:06:01.609+0000] {taskinstance.py:1956} INFO - Dependencies all met for dep_context=requeueable deps ti=<TaskInstance: e_commerce_dw_etl.extract.extract_and_load_to_staging scheduled__2024-12-17T00:00:00+00:00 [queued]>
[2025-05-08T11:06:01.610+0000] {taskinstance.py:2170} INFO - Starting attempt 1 of 1
[2025-05-08T11:06:01.633+0000] {taskinstance.py:2191} INFO - Executing <Task(PythonOperator): extract.extract_and_load_to_staging> on 2024-12-17 00:00:00+00:00
[2025-05-08T11:06:01.639+0000] {standard_task_runner.py:60} INFO - Started process 426 to run task
[2025-05-08T11:06:01.648+0000] {standard_task_runner.py:87} INFO - Running: ['***', 'tasks', 'run', 'e_commerce_dw_etl', 'extract.extract_and_load_to_staging', 'scheduled__2024-12-17T00:00:00+00:00', '--job-id', '940', '--raw', '--subdir', 'DAGS_FOLDER/e_commerce_dw_dag.py', '--cfg-path', '/tmp/tmpvcb70e5y']
[2025-05-08T11:06:01.652+0000] {standard_task_runner.py:88} INFO - Job 940: Subtask extract.extract_and_load_to_staging
[2025-05-08T11:06:01.871+0000] {logging_mixin.py:188} WARNING - /home/***/.local/lib/python3.8/site-packages/***/settings.py:194 DeprecationWarning: The sql_alchemy_conn option in [core] has been moved to the sql_alchemy_conn option in [database] - the old setting has been used, but please update your config.
[2025-05-08T11:06:01.917+0000] {task_command.py:423} INFO - Running <TaskInstance: e_commerce_dw_etl.extract.extract_and_load_to_staging scheduled__2024-12-17T00:00:00+00:00 [running]> on host 14e98ede325e
[2025-05-08T11:06:02.022+0000] {taskinstance.py:2480} INFO - Exporting env vars: AIRFLOW_CTX_DAG_OWNER='***' AIRFLOW_CTX_DAG_ID='e_commerce_dw_etl' AIRFLOW_CTX_TASK_ID='extract.extract_and_load_to_staging' AIRFLOW_CTX_EXECUTION_DATE='2024-12-17T00:00:00+00:00' AIRFLOW_CTX_TRY_NUMBER='1' AIRFLOW_CTX_DAG_RUN_ID='scheduled__2024-12-17T00:00:00+00:00'
[2025-05-08T11:06:02.041+0000] {mysql_operator.py:13} ERROR - Can't connect to mysql database
[2025-05-08T11:06:02.066+0000] {taskinstance.py:2698} ERROR - Task failed with exception
Traceback (most recent call last):
  File "/home/airflow/.local/lib/python3.8/site-packages/airflow/models/taskinstance.py", line 433, in _execute_task
    result = execute_callable(context=context, **execute_callable_kwargs)
  File "/home/airflow/.local/lib/python3.8/site-packages/airflow/operators/python.py", line 199, in execute
    return_value = self.execute_callable()
  File "/home/airflow/.local/lib/python3.8/site-packages/airflow/operators/python.py", line 216, in execute_callable
    return self.python_callable(*self.op_args, **self.op_kwargs)
  File "/opt/airflow/dags/extract_data.py", line 30, in extract_and_load_to_staging
    df = source_operator.get_data_to_pd(f"SELECT * FROM {table}")
  File "/opt/airflow/plugins/mysql_operator.py", line 15, in get_data_to_pd
    return self.mysqlhook.get_pandas_df(query)
  File "/home/airflow/.local/lib/python3.8/site-packages/airflow/providers/common/sql/hooks/sql.py", line 220, in get_pandas_df
    with closing(self.get_conn()) as conn:
  File "/home/airflow/.local/lib/python3.8/site-packages/airflow/providers/mysql/hooks/mysql.py", line 187, in get_conn
    conn = self.connection or self.get_connection(getattr(self, self.conn_name_attr))
  File "/home/airflow/.local/lib/python3.8/site-packages/airflow/hooks/base.py", line 82, in get_connection
    conn = Connection.get_connection_from_secrets(conn_id)
  File "/home/airflow/.local/lib/python3.8/site-packages/airflow/models/connection.py", line 479, in get_connection_from_secrets
    raise AirflowNotFoundException(f"The conn_id `{conn_id}` isn't defined")
airflow.exceptions.AirflowNotFoundException: The conn_id `mysql` isn't defined
[2025-05-08T11:06:02.079+0000] {taskinstance.py:1138} INFO - Marking task as FAILED. dag_id=e_commerce_dw_etl, task_id=extract.extract_and_load_to_staging, execution_date=20241217T000000, start_date=20250508T110601, end_date=20250508T110602
[2025-05-08T11:06:02.184+0000] {standard_task_runner.py:107} ERROR - Failed to execute job 940 for task extract.extract_and_load_to_staging (The conn_id `mysql` isn't defined; 426)
[2025-05-08T11:06:02.217+0000] {local_task_job_runner.py:234} INFO - Task exited with return code 1
[2025-05-08T11:06:02.482+0000] {taskinstance.py:3280} INFO - 0 downstream tasks scheduled from follow-on schedule check
[2025-05-08T11:09:00.139+0000] {taskinstance.py:1956} INFO - Dependencies all met for dep_context=non-requeueable deps ti=<TaskInstance: e_commerce_dw_etl.extract.extract_and_load_to_staging scheduled__2024-12-17T00:00:00+00:00 [queued]>
[2025-05-08T11:09:00.153+0000] {taskinstance.py:1956} INFO - Dependencies all met for dep_context=requeueable deps ti=<TaskInstance: e_commerce_dw_etl.extract.extract_and_load_to_staging scheduled__2024-12-17T00:00:00+00:00 [queued]>
[2025-05-08T11:09:00.154+0000] {taskinstance.py:2170} INFO - Starting attempt 1 of 1
[2025-05-08T11:09:00.175+0000] {taskinstance.py:2191} INFO - Executing <Task(PythonOperator): extract.extract_and_load_to_staging> on 2024-12-17 00:00:00+00:00
[2025-05-08T11:09:00.181+0000] {standard_task_runner.py:60} INFO - Started process 911 to run task
[2025-05-08T11:09:00.184+0000] {standard_task_runner.py:87} INFO - Running: ['***', 'tasks', 'run', 'e_commerce_dw_etl', 'extract.extract_and_load_to_staging', 'scheduled__2024-12-17T00:00:00+00:00', '--job-id', '1134', '--raw', '--subdir', 'DAGS_FOLDER/e_commerce_dw_dag.py', '--cfg-path', '/tmp/tmpbbia3nqp']
[2025-05-08T11:09:00.186+0000] {standard_task_runner.py:88} INFO - Job 1134: Subtask extract.extract_and_load_to_staging
[2025-05-08T11:09:00.339+0000] {logging_mixin.py:188} WARNING - /home/***/.local/lib/python3.8/site-packages/***/settings.py:194 DeprecationWarning: The sql_alchemy_conn option in [core] has been moved to the sql_alchemy_conn option in [database] - the old setting has been used, but please update your config.
[2025-05-08T11:09:00.369+0000] {task_command.py:423} INFO - Running <TaskInstance: e_commerce_dw_etl.extract.extract_and_load_to_staging scheduled__2024-12-17T00:00:00+00:00 [running]> on host 14e98ede325e
[2025-05-08T11:09:00.442+0000] {taskinstance.py:2480} INFO - Exporting env vars: AIRFLOW_CTX_DAG_OWNER='***' AIRFLOW_CTX_DAG_ID='e_commerce_dw_etl' AIRFLOW_CTX_TASK_ID='extract.extract_and_load_to_staging' AIRFLOW_CTX_EXECUTION_DATE='2024-12-17T00:00:00+00:00' AIRFLOW_CTX_TRY_NUMBER='1' AIRFLOW_CTX_DAG_RUN_ID='scheduled__2024-12-17T00:00:00+00:00'
[2025-05-08T11:09:00.449+0000] {crypto.py:82} WARNING - empty cryptography key - values will not be stored encrypted.
[2025-05-08T11:09:00.450+0000] {connection.py:473} ERROR - Unable to retrieve connection from secrets backend (MetastoreBackend). Checking subsequent secrets backend.
Traceback (most recent call last):
  File "/home/airflow/.local/lib/python3.8/site-packages/airflow/models/connection.py", line 468, in get_connection_from_secrets
    conn = secrets_backend.get_connection(conn_id=conn_id)
  File "/home/airflow/.local/lib/python3.8/site-packages/airflow/utils/session.py", line 79, in wrapper
    return func(*args, session=session, **kwargs)
  File "/home/airflow/.local/lib/python3.8/site-packages/airflow/secrets/metastore.py", line 42, in get_connection
    return MetastoreBackend._fetch_connection(conn_id, session=session)
  File "/home/airflow/.local/lib/python3.8/site-packages/airflow/api_internal/internal_api_call.py", line 114, in wrapper
    return func(*args, **kwargs)
  File "/home/airflow/.local/lib/python3.8/site-packages/airflow/utils/session.py", line 76, in wrapper
    return func(*args, **kwargs)
  File "/home/airflow/.local/lib/python3.8/site-packages/airflow/secrets/metastore.py", line 73, in _fetch_connection
    conn = session.scalar(select(Connection).where(Connection.conn_id == conn_id).limit(1))
  File "/home/airflow/.local/lib/python3.8/site-packages/sqlalchemy/orm/session.py", line 1747, in scalar
    return self.execute(
  File "/home/airflow/.local/lib/python3.8/site-packages/sqlalchemy/engine/result.py", line 1276, in scalar
    return self._only_one_row(
  File "/home/airflow/.local/lib/python3.8/site-packages/sqlalchemy/engine/result.py", line 559, in _only_one_row
    row = onerow(hard_close=True)
  File "/home/airflow/.local/lib/python3.8/site-packages/sqlalchemy/engine/result.py", line 1801, in _fetchone_impl
    row = next(self.iterator, _NO_ROW)
  File "/home/airflow/.local/lib/python3.8/site-packages/sqlalchemy/orm/loading.py", line 151, in chunks
    rows = [proc(row) for row in fetch]
  File "/home/airflow/.local/lib/python3.8/site-packages/sqlalchemy/orm/loading.py", line 151, in <listcomp>
    rows = [proc(row) for row in fetch]
  File "/home/airflow/.local/lib/python3.8/site-packages/sqlalchemy/orm/loading.py", line 984, in _instance
    state.manager.dispatch.load(state, context)
  File "/home/airflow/.local/lib/python3.8/site-packages/sqlalchemy/event/attr.py", line 346, in __call__
    fn(*args, **kw)
  File "/home/airflow/.local/lib/python3.8/site-packages/sqlalchemy/orm/mapper.py", line 3702, in _event_on_load
    instrumenting_mapper._reconstructor(state.obj())
  File "/home/airflow/.local/lib/python3.8/site-packages/airflow/models/connection.py", line 174, in on_db_load
    if self.password:
  File "/home/airflow/.local/lib/python3.8/site-packages/sqlalchemy/orm/attributes.py", line 606, in __get__
    retval = self.descriptor.__get__(instance, owner)
  File "/home/airflow/.local/lib/python3.8/site-packages/airflow/models/connection.py", line 296, in get_password
    raise AirflowException(
airflow.exceptions.AirflowException: Can't decrypt encrypted password for login=***  FERNET_KEY configuration is missing
[2025-05-08T11:09:00.453+0000] {mysql_operator.py:13} ERROR - Can't connect to mysql database
[2025-05-08T11:09:00.460+0000] {connection.py:473} ERROR - Unable to retrieve connection from secrets backend (MetastoreBackend). Checking subsequent secrets backend.
Traceback (most recent call last):
  File "/home/airflow/.local/lib/python3.8/site-packages/airflow/models/connection.py", line 468, in get_connection_from_secrets
    conn = secrets_backend.get_connection(conn_id=conn_id)
  File "/home/airflow/.local/lib/python3.8/site-packages/airflow/utils/session.py", line 79, in wrapper
    return func(*args, session=session, **kwargs)
  File "/home/airflow/.local/lib/python3.8/site-packages/airflow/secrets/metastore.py", line 42, in get_connection
    return MetastoreBackend._fetch_connection(conn_id, session=session)
  File "/home/airflow/.local/lib/python3.8/site-packages/airflow/api_internal/internal_api_call.py", line 114, in wrapper
    return func(*args, **kwargs)
  File "/home/airflow/.local/lib/python3.8/site-packages/airflow/utils/session.py", line 76, in wrapper
    return func(*args, **kwargs)
  File "/home/airflow/.local/lib/python3.8/site-packages/airflow/secrets/metastore.py", line 73, in _fetch_connection
    conn = session.scalar(select(Connection).where(Connection.conn_id == conn_id).limit(1))
  File "/home/airflow/.local/lib/python3.8/site-packages/sqlalchemy/orm/session.py", line 1747, in scalar
    return self.execute(
  File "/home/airflow/.local/lib/python3.8/site-packages/sqlalchemy/engine/result.py", line 1276, in scalar
    return self._only_one_row(
  File "/home/airflow/.local/lib/python3.8/site-packages/sqlalchemy/engine/result.py", line 559, in _only_one_row
    row = onerow(hard_close=True)
  File "/home/airflow/.local/lib/python3.8/site-packages/sqlalchemy/engine/result.py", line 1801, in _fetchone_impl
    row = next(self.iterator, _NO_ROW)
  File "/home/airflow/.local/lib/python3.8/site-packages/sqlalchemy/orm/loading.py", line 151, in chunks
    rows = [proc(row) for row in fetch]
  File "/home/airflow/.local/lib/python3.8/site-packages/sqlalchemy/orm/loading.py", line 151, in <listcomp>
    rows = [proc(row) for row in fetch]
  File "/home/airflow/.local/lib/python3.8/site-packages/sqlalchemy/orm/loading.py", line 984, in _instance
    state.manager.dispatch.load(state, context)
  File "/home/airflow/.local/lib/python3.8/site-packages/sqlalchemy/event/attr.py", line 346, in __call__
    fn(*args, **kw)
  File "/home/airflow/.local/lib/python3.8/site-packages/sqlalchemy/orm/mapper.py", line 3702, in _event_on_load
    instrumenting_mapper._reconstructor(state.obj())
  File "/home/airflow/.local/lib/python3.8/site-packages/airflow/models/connection.py", line 174, in on_db_load
    if self.password:
  File "/home/airflow/.local/lib/python3.8/site-packages/sqlalchemy/orm/attributes.py", line 606, in __get__
    retval = self.descriptor.__get__(instance, owner)
  File "/home/airflow/.local/lib/python3.8/site-packages/airflow/models/connection.py", line 296, in get_password
    raise AirflowException(
airflow.exceptions.AirflowException: Can't decrypt encrypted password for login=***  FERNET_KEY configuration is missing
[2025-05-08T11:09:00.469+0000] {taskinstance.py:2698} ERROR - Task failed with exception
Traceback (most recent call last):
  File "/home/airflow/.local/lib/python3.8/site-packages/airflow/models/taskinstance.py", line 433, in _execute_task
    result = execute_callable(context=context, **execute_callable_kwargs)
  File "/home/airflow/.local/lib/python3.8/site-packages/airflow/operators/python.py", line 199, in execute
    return_value = self.execute_callable()
  File "/home/airflow/.local/lib/python3.8/site-packages/airflow/operators/python.py", line 216, in execute_callable
    return self.python_callable(*self.op_args, **self.op_kwargs)
  File "/opt/airflow/dags/extract_data.py", line 30, in extract_and_load_to_staging
    df = source_operator.get_data_to_pd(f"SELECT * FROM {table}")
  File "/opt/airflow/plugins/mysql_operator.py", line 15, in get_data_to_pd
    return self.mysqlhook.get_pandas_df(query)
  File "/home/airflow/.local/lib/python3.8/site-packages/airflow/providers/common/sql/hooks/sql.py", line 220, in get_pandas_df
    with closing(self.get_conn()) as conn:
  File "/home/airflow/.local/lib/python3.8/site-packages/airflow/providers/mysql/hooks/mysql.py", line 187, in get_conn
    conn = self.connection or self.get_connection(getattr(self, self.conn_name_attr))
  File "/home/airflow/.local/lib/python3.8/site-packages/airflow/hooks/base.py", line 82, in get_connection
    conn = Connection.get_connection_from_secrets(conn_id)
  File "/home/airflow/.local/lib/python3.8/site-packages/airflow/models/connection.py", line 479, in get_connection_from_secrets
    raise AirflowNotFoundException(f"The conn_id `{conn_id}` isn't defined")
airflow.exceptions.AirflowNotFoundException: The conn_id `mysql` isn't defined
[2025-05-08T11:09:00.482+0000] {taskinstance.py:1138} INFO - Marking task as FAILED. dag_id=e_commerce_dw_etl, task_id=extract.extract_and_load_to_staging, execution_date=20241217T000000, start_date=20250508T110900, end_date=20250508T110900
[2025-05-08T11:09:00.494+0000] {standard_task_runner.py:107} ERROR - Failed to execute job 1134 for task extract.extract_and_load_to_staging (The conn_id `mysql` isn't defined; 911)
[2025-05-08T11:09:00.518+0000] {local_task_job_runner.py:234} INFO - Task exited with return code 1
[2025-05-08T11:09:00.636+0000] {taskinstance.py:3280} INFO - 0 downstream tasks scheduled from follow-on schedule check
[2025-05-08T11:14:55.081+0000] {taskinstance.py:1956} INFO - Dependencies all met for dep_context=non-requeueable deps ti=<TaskInstance: e_commerce_dw_etl.extract.extract_and_load_to_staging scheduled__2024-12-17T00:00:00+00:00 [queued]>
[2025-05-08T11:14:55.096+0000] {taskinstance.py:1956} INFO - Dependencies all met for dep_context=requeueable deps ti=<TaskInstance: e_commerce_dw_etl.extract.extract_and_load_to_staging scheduled__2024-12-17T00:00:00+00:00 [queued]>
[2025-05-08T11:14:55.097+0000] {taskinstance.py:2170} INFO - Starting attempt 1 of 1
[2025-05-08T11:14:55.174+0000] {taskinstance.py:2191} INFO - Executing <Task(PythonOperator): extract.extract_and_load_to_staging> on 2024-12-17 00:00:00+00:00
[2025-05-08T11:14:55.183+0000] {standard_task_runner.py:60} INFO - Started process 338 to run task
[2025-05-08T11:14:55.189+0000] {standard_task_runner.py:87} INFO - Running: ['***', 'tasks', 'run', 'e_commerce_dw_etl', 'extract.extract_and_load_to_staging', 'scheduled__2024-12-17T00:00:00+00:00', '--job-id', '1329', '--raw', '--subdir', 'DAGS_FOLDER/e_commerce_dw_dag.py', '--cfg-path', '/tmp/tmp32y03szg']
[2025-05-08T11:14:55.193+0000] {standard_task_runner.py:88} INFO - Job 1329: Subtask extract.extract_and_load_to_staging
[2025-05-08T11:14:55.397+0000] {logging_mixin.py:188} WARNING - /home/***/.local/lib/python3.8/site-packages/***/settings.py:194 DeprecationWarning: The sql_alchemy_conn option in [core] has been moved to the sql_alchemy_conn option in [database] - the old setting has been used, but please update your config.
[2025-05-08T11:14:55.447+0000] {task_command.py:423} INFO - Running <TaskInstance: e_commerce_dw_etl.extract.extract_and_load_to_staging scheduled__2024-12-17T00:00:00+00:00 [running]> on host 3623a279d4d4
[2025-05-08T11:14:55.554+0000] {taskinstance.py:2480} INFO - Exporting env vars: AIRFLOW_CTX_DAG_OWNER='***' AIRFLOW_CTX_DAG_ID='e_commerce_dw_etl' AIRFLOW_CTX_TASK_ID='extract.extract_and_load_to_staging' AIRFLOW_CTX_EXECUTION_DATE='2024-12-17T00:00:00+00:00' AIRFLOW_CTX_TRY_NUMBER='1' AIRFLOW_CTX_DAG_RUN_ID='scheduled__2024-12-17T00:00:00+00:00'
[2025-05-08T11:14:55.563+0000] {mysql_operator.py:13} ERROR - Can't connect to mysql_default database
[2025-05-08T11:14:55.579+0000] {taskinstance.py:2698} ERROR - Task failed with exception
Traceback (most recent call last):
  File "/home/airflow/.local/lib/python3.8/site-packages/airflow/models/taskinstance.py", line 433, in _execute_task
    result = execute_callable(context=context, **execute_callable_kwargs)
  File "/home/airflow/.local/lib/python3.8/site-packages/airflow/operators/python.py", line 199, in execute
    return_value = self.execute_callable()
  File "/home/airflow/.local/lib/python3.8/site-packages/airflow/operators/python.py", line 216, in execute_callable
    return self.python_callable(*self.op_args, **self.op_kwargs)
  File "/opt/airflow/dags/extract_data.py", line 30, in extract_and_load_to_staging
    df = source_operator.get_data_to_pd(f"SELECT * FROM {table}")
  File "/opt/airflow/plugins/mysql_operator.py", line 15, in get_data_to_pd
    return self.mysqlhook.get_pandas_df(query)
  File "/home/airflow/.local/lib/python3.8/site-packages/airflow/providers/common/sql/hooks/sql.py", line 220, in get_pandas_df
    with closing(self.get_conn()) as conn:
  File "/home/airflow/.local/lib/python3.8/site-packages/airflow/providers/mysql/hooks/mysql.py", line 187, in get_conn
    conn = self.connection or self.get_connection(getattr(self, self.conn_name_attr))
  File "/home/airflow/.local/lib/python3.8/site-packages/airflow/hooks/base.py", line 82, in get_connection
    conn = Connection.get_connection_from_secrets(conn_id)
  File "/home/airflow/.local/lib/python3.8/site-packages/airflow/models/connection.py", line 479, in get_connection_from_secrets
    raise AirflowNotFoundException(f"The conn_id `{conn_id}` isn't defined")
airflow.exceptions.AirflowNotFoundException: The conn_id `mysql_default` isn't defined
[2025-05-08T11:14:55.590+0000] {taskinstance.py:1138} INFO - Marking task as FAILED. dag_id=e_commerce_dw_etl, task_id=extract.extract_and_load_to_staging, execution_date=20241217T000000, start_date=20250508T111455, end_date=20250508T111455
[2025-05-08T11:14:55.605+0000] {standard_task_runner.py:107} ERROR - Failed to execute job 1329 for task extract.extract_and_load_to_staging (The conn_id `mysql_default` isn't defined; 338)
[2025-05-08T11:14:55.645+0000] {local_task_job_runner.py:234} INFO - Task exited with return code 1
[2025-05-08T11:14:55.829+0000] {taskinstance.py:3280} INFO - 0 downstream tasks scheduled from follow-on schedule check
[2025-05-08T11:20:04.392+0000] {taskinstance.py:1956} INFO - Dependencies all met for dep_context=non-requeueable deps ti=<TaskInstance: e_commerce_dw_etl.extract.extract_and_load_to_staging scheduled__2024-12-17T00:00:00+00:00 [queued]>
[2025-05-08T11:20:04.410+0000] {taskinstance.py:1956} INFO - Dependencies all met for dep_context=requeueable deps ti=<TaskInstance: e_commerce_dw_etl.extract.extract_and_load_to_staging scheduled__2024-12-17T00:00:00+00:00 [queued]>
[2025-05-08T11:20:04.411+0000] {taskinstance.py:2170} INFO - Starting attempt 1 of 1
[2025-05-08T11:20:04.458+0000] {taskinstance.py:2191} INFO - Executing <Task(PythonOperator): extract.extract_and_load_to_staging> on 2024-12-17 00:00:00+00:00
[2025-05-08T11:20:04.467+0000] {standard_task_runner.py:60} INFO - Started process 1132 to run task
[2025-05-08T11:20:04.474+0000] {standard_task_runner.py:87} INFO - Running: ['***', 'tasks', 'run', 'e_commerce_dw_etl', 'extract.extract_and_load_to_staging', 'scheduled__2024-12-17T00:00:00+00:00', '--job-id', '1624', '--raw', '--subdir', 'DAGS_FOLDER/e_commerce_dw_dag.py', '--cfg-path', '/tmp/tmphd7ld2rq']
[2025-05-08T11:20:04.477+0000] {standard_task_runner.py:88} INFO - Job 1624: Subtask extract.extract_and_load_to_staging
[2025-05-08T11:20:04.665+0000] {logging_mixin.py:188} WARNING - /home/***/.local/lib/python3.8/site-packages/***/settings.py:194 DeprecationWarning: The sql_alchemy_conn option in [core] has been moved to the sql_alchemy_conn option in [database] - the old setting has been used, but please update your config.
[2025-05-08T11:20:04.715+0000] {task_command.py:423} INFO - Running <TaskInstance: e_commerce_dw_etl.extract.extract_and_load_to_staging scheduled__2024-12-17T00:00:00+00:00 [running]> on host 3623a279d4d4
[2025-05-08T11:20:04.805+0000] {taskinstance.py:2480} INFO - Exporting env vars: AIRFLOW_CTX_DAG_OWNER='***' AIRFLOW_CTX_DAG_ID='e_commerce_dw_etl' AIRFLOW_CTX_TASK_ID='extract.extract_and_load_to_staging' AIRFLOW_CTX_EXECUTION_DATE='2024-12-17T00:00:00+00:00' AIRFLOW_CTX_TRY_NUMBER='1' AIRFLOW_CTX_DAG_RUN_ID='scheduled__2024-12-17T00:00:00+00:00'
[2025-05-08T11:20:04.817+0000] {crypto.py:82} WARNING - empty cryptography key - values will not be stored encrypted.
[2025-05-08T11:20:04.819+0000] {connection.py:473} ERROR - Unable to retrieve connection from secrets backend (MetastoreBackend). Checking subsequent secrets backend.
Traceback (most recent call last):
  File "/home/airflow/.local/lib/python3.8/site-packages/airflow/models/connection.py", line 468, in get_connection_from_secrets
    conn = secrets_backend.get_connection(conn_id=conn_id)
  File "/home/airflow/.local/lib/python3.8/site-packages/airflow/utils/session.py", line 79, in wrapper
    return func(*args, session=session, **kwargs)
  File "/home/airflow/.local/lib/python3.8/site-packages/airflow/secrets/metastore.py", line 42, in get_connection
    return MetastoreBackend._fetch_connection(conn_id, session=session)
  File "/home/airflow/.local/lib/python3.8/site-packages/airflow/api_internal/internal_api_call.py", line 114, in wrapper
    return func(*args, **kwargs)
  File "/home/airflow/.local/lib/python3.8/site-packages/airflow/utils/session.py", line 76, in wrapper
    return func(*args, **kwargs)
  File "/home/airflow/.local/lib/python3.8/site-packages/airflow/secrets/metastore.py", line 73, in _fetch_connection
    conn = session.scalar(select(Connection).where(Connection.conn_id == conn_id).limit(1))
  File "/home/airflow/.local/lib/python3.8/site-packages/sqlalchemy/orm/session.py", line 1747, in scalar
    return self.execute(
  File "/home/airflow/.local/lib/python3.8/site-packages/sqlalchemy/engine/result.py", line 1276, in scalar
    return self._only_one_row(
  File "/home/airflow/.local/lib/python3.8/site-packages/sqlalchemy/engine/result.py", line 559, in _only_one_row
    row = onerow(hard_close=True)
  File "/home/airflow/.local/lib/python3.8/site-packages/sqlalchemy/engine/result.py", line 1801, in _fetchone_impl
    row = next(self.iterator, _NO_ROW)
  File "/home/airflow/.local/lib/python3.8/site-packages/sqlalchemy/orm/loading.py", line 151, in chunks
    rows = [proc(row) for row in fetch]
  File "/home/airflow/.local/lib/python3.8/site-packages/sqlalchemy/orm/loading.py", line 151, in <listcomp>
    rows = [proc(row) for row in fetch]
  File "/home/airflow/.local/lib/python3.8/site-packages/sqlalchemy/orm/loading.py", line 984, in _instance
    state.manager.dispatch.load(state, context)
  File "/home/airflow/.local/lib/python3.8/site-packages/sqlalchemy/event/attr.py", line 346, in __call__
    fn(*args, **kw)
  File "/home/airflow/.local/lib/python3.8/site-packages/sqlalchemy/orm/mapper.py", line 3702, in _event_on_load
    instrumenting_mapper._reconstructor(state.obj())
  File "/home/airflow/.local/lib/python3.8/site-packages/airflow/models/connection.py", line 174, in on_db_load
    if self.password:
  File "/home/airflow/.local/lib/python3.8/site-packages/sqlalchemy/orm/attributes.py", line 606, in __get__
    retval = self.descriptor.__get__(instance, owner)
  File "/home/airflow/.local/lib/python3.8/site-packages/airflow/models/connection.py", line 296, in get_password
    raise AirflowException(
airflow.exceptions.AirflowException: Can't decrypt encrypted password for login=***  FERNET_KEY configuration is missing
[2025-05-08T11:20:04.823+0000] {mysql_operator.py:13} ERROR - Can't connect to mysql database
[2025-05-08T11:20:04.832+0000] {connection.py:473} ERROR - Unable to retrieve connection from secrets backend (MetastoreBackend). Checking subsequent secrets backend.
Traceback (most recent call last):
  File "/home/airflow/.local/lib/python3.8/site-packages/airflow/models/connection.py", line 468, in get_connection_from_secrets
    conn = secrets_backend.get_connection(conn_id=conn_id)
  File "/home/airflow/.local/lib/python3.8/site-packages/airflow/utils/session.py", line 79, in wrapper
    return func(*args, session=session, **kwargs)
  File "/home/airflow/.local/lib/python3.8/site-packages/airflow/secrets/metastore.py", line 42, in get_connection
    return MetastoreBackend._fetch_connection(conn_id, session=session)
  File "/home/airflow/.local/lib/python3.8/site-packages/airflow/api_internal/internal_api_call.py", line 114, in wrapper
    return func(*args, **kwargs)
  File "/home/airflow/.local/lib/python3.8/site-packages/airflow/utils/session.py", line 76, in wrapper
    return func(*args, **kwargs)
  File "/home/airflow/.local/lib/python3.8/site-packages/airflow/secrets/metastore.py", line 73, in _fetch_connection
    conn = session.scalar(select(Connection).where(Connection.conn_id == conn_id).limit(1))
  File "/home/airflow/.local/lib/python3.8/site-packages/sqlalchemy/orm/session.py", line 1747, in scalar
    return self.execute(
  File "/home/airflow/.local/lib/python3.8/site-packages/sqlalchemy/engine/result.py", line 1276, in scalar
    return self._only_one_row(
  File "/home/airflow/.local/lib/python3.8/site-packages/sqlalchemy/engine/result.py", line 559, in _only_one_row
    row = onerow(hard_close=True)
  File "/home/airflow/.local/lib/python3.8/site-packages/sqlalchemy/engine/result.py", line 1801, in _fetchone_impl
    row = next(self.iterator, _NO_ROW)
  File "/home/airflow/.local/lib/python3.8/site-packages/sqlalchemy/orm/loading.py", line 151, in chunks
    rows = [proc(row) for row in fetch]
  File "/home/airflow/.local/lib/python3.8/site-packages/sqlalchemy/orm/loading.py", line 151, in <listcomp>
    rows = [proc(row) for row in fetch]
  File "/home/airflow/.local/lib/python3.8/site-packages/sqlalchemy/orm/loading.py", line 984, in _instance
    state.manager.dispatch.load(state, context)
  File "/home/airflow/.local/lib/python3.8/site-packages/sqlalchemy/event/attr.py", line 346, in __call__
    fn(*args, **kw)
  File "/home/airflow/.local/lib/python3.8/site-packages/sqlalchemy/orm/mapper.py", line 3702, in _event_on_load
    instrumenting_mapper._reconstructor(state.obj())
  File "/home/airflow/.local/lib/python3.8/site-packages/airflow/models/connection.py", line 174, in on_db_load
    if self.password:
  File "/home/airflow/.local/lib/python3.8/site-packages/sqlalchemy/orm/attributes.py", line 606, in __get__
    retval = self.descriptor.__get__(instance, owner)
  File "/home/airflow/.local/lib/python3.8/site-packages/airflow/models/connection.py", line 296, in get_password
    raise AirflowException(
airflow.exceptions.AirflowException: Can't decrypt encrypted password for login=***  FERNET_KEY configuration is missing
[2025-05-08T11:20:04.844+0000] {taskinstance.py:2698} ERROR - Task failed with exception
Traceback (most recent call last):
  File "/home/airflow/.local/lib/python3.8/site-packages/airflow/models/taskinstance.py", line 433, in _execute_task
    result = execute_callable(context=context, **execute_callable_kwargs)
  File "/home/airflow/.local/lib/python3.8/site-packages/airflow/operators/python.py", line 199, in execute
    return_value = self.execute_callable()
  File "/home/airflow/.local/lib/python3.8/site-packages/airflow/operators/python.py", line 216, in execute_callable
    return self.python_callable(*self.op_args, **self.op_kwargs)
  File "/opt/airflow/dags/extract_data.py", line 30, in extract_and_load_to_staging
    df = source_operator.get_data_to_pd(f"SELECT * FROM {table}")
  File "/opt/airflow/plugins/mysql_operator.py", line 15, in get_data_to_pd
    return self.mysqlhook.get_pandas_df(query)
  File "/home/airflow/.local/lib/python3.8/site-packages/airflow/providers/common/sql/hooks/sql.py", line 220, in get_pandas_df
    with closing(self.get_conn()) as conn:
  File "/home/airflow/.local/lib/python3.8/site-packages/airflow/providers/mysql/hooks/mysql.py", line 187, in get_conn
    conn = self.connection or self.get_connection(getattr(self, self.conn_name_attr))
  File "/home/airflow/.local/lib/python3.8/site-packages/airflow/hooks/base.py", line 82, in get_connection
    conn = Connection.get_connection_from_secrets(conn_id)
  File "/home/airflow/.local/lib/python3.8/site-packages/airflow/models/connection.py", line 479, in get_connection_from_secrets
    raise AirflowNotFoundException(f"The conn_id `{conn_id}` isn't defined")
airflow.exceptions.AirflowNotFoundException: The conn_id `mysql` isn't defined
[2025-05-08T11:20:04.859+0000] {taskinstance.py:1138} INFO - Marking task as FAILED. dag_id=e_commerce_dw_etl, task_id=extract.extract_and_load_to_staging, execution_date=20241217T000000, start_date=20250508T112004, end_date=20250508T112004
[2025-05-08T11:20:04.872+0000] {standard_task_runner.py:107} ERROR - Failed to execute job 1624 for task extract.extract_and_load_to_staging (The conn_id `mysql` isn't defined; 1132)
[2025-05-08T11:20:04.928+0000] {local_task_job_runner.py:234} INFO - Task exited with return code 1
[2025-05-08T11:20:05.060+0000] {taskinstance.py:3280} INFO - 0 downstream tasks scheduled from follow-on schedule check
